Workbook

Sheet Members
A1: ลำดับ | B1: ชื่อ - สกุล | C1: ชื่อเล่น | D1: เบอร์โทร | E1: เลขบัญชี | F1: ตัวย่อธนาคาร | G1: ชื่อธนาคาร | H1: สังกัด | I1: วันที่เริ่มงาน
A2: 1 | B2: ธัญชนก เรืองฤทธิ์ | C2: ธัญ | D2: 0915519826 | E2: 1811299134 | F2: K-BANK | G2: =IFERROR(_xlfn.XLOOKUP(F2,K:K,L:L),"") | H2: BM1
A3: 2 | B3: ธนาธิป ควรสำโรง | C3: ดรีม | D3: 0930696696 | E3: 1218153972 | F3: K-BANK | G3: =IFERROR(_xlfn.XLOOKUP(F3,K:K,L:L),"") | H3: BM1 | K3: BANK NAME | L3: BANK NAME (THAI)
A4: 3 | B4: ปนิดา กะประโคน | C4: โบนัส | D4: 0803726832 | E4: 7420348547 | F4: BBL | G4: =IFERROR(_xlfn.XLOOKUP(F4,K:K,L:L),"") | H4: BM1 | K4: K-BANK | L4: กสิกรไทย
A5: 4 | B5: ฮาดีบ๊ะ ตีเยาะ | C5: บ้ะ | D5: 0926867010 | E5: 9020252285 | F5: BBL | G5: =IFERROR(_xlfn.XLOOKUP(F5,K:K,L:L),"") | H5: BM1 | K5: BBL | L5: กรุงเทพ
A6: 5 | B6: เกณิกา ฐาณัตตระกูล | C6: เก | D6: 0636209425 | E6: 9219444982 | F6: TTB | G6: =IFERROR(_xlfn.XLOOKUP(F6,K:K,L:L),"") | H6: BM1 | K6: GSB | L6: ออมสิน
A7: 6 | B7: อรุณี ต้นฟู | C7: ผึ้ง | D7: 0979243743 | E7: 4081849057 | F7: SCB | G7: =IFERROR(_xlfn.XLOOKUP(F7,K:K,L:L),"") | H7: BM1 | K7: BAY | L7: กรุงศรีอยุธยา
A8: 7 | B8: ฟารดา สารจันทร์ | C8: ฟาน | D8: 0937412326 | E8: 4113361800 | F8: KTB | G8: =IFERROR(_xlfn.XLOOKUP(F8,K:K,L:L),"") | H8: BM1 | K8: SCB | L8: ไทยพาณิชย์
A9: 8 | B9: ตูแวยะ ลอมะ | C9: ยะห์ | D9: 0968944755 | E9: 1924391905 | F9: BBL | G9: =IFERROR(_xlfn.XLOOKUP(F9,K:K,L:L),"") | H9: BM1 | K9: KTB | L9: กรุงไทย
A10: 9 | B10: สาธิกา ชาญกล | C10: ลูกอิน | D10: 0980549042 | E10: 4200292566 | F10: BBL | G10: =IFERROR(_xlfn.XLOOKUP(F10,K:K,L:L),"") | H10: BM1 | K10: TTB | L10: ทหารไทยธนชาต จำกัด (มหาชน)
A11: 10 | B11: สุริยะ สาลีทอง | C11: ต้น | D11: - | E11: 052630993385 | F11: GSB | G11: =IFERROR(_xlfn.XLOOKUP(F11,K:K,L:L),"") | H11: BM3 | K11: KKP | L11: เกียรตินาคิน
A12: 11 | B12: พงษ์ทวี เข็มเพ็ชร | C12: เบียร์ | D12: 0829701196 | E12: 2012804468 | F12: SCB | G12: =IFERROR(_xlfn.XLOOKUP(F12,K:K,L:L),"") | H12: BM1 | K12: BAAC | L12: ธ.ก.ส.
A13: 12 | B13: ธนสิน จินดามณี | C13: ออม | D13: 0986732294 | E13: 2012855964 | F13: SCB | G13: =IFERROR(_xlfn.XLOOKUP(F13,K:K,L:L),"") | H13: BM1 | K13: UOB | L13: ยูโอบี
A14: 13 | B14: ยุภา พุทธรัตน์ | C14: ก้อย | D14: 0981655859 | E14: 4321404575 | F14: SCB | G14: =IFERROR(_xlfn.XLOOKUP(F14,K:K,L:L),"") | H14: BM1
A15: 14 | B15: อมรา ปรีชาชาญ | C15: หนิง | D15: 0924968786 | E15: 1462883642 | F15: SCB | G15: =IFERROR(_xlfn.XLOOKUP(F15,K:K,L:L),"") | H15: BM1
A16: 15 | B16: สุริยา ลีมา | C16: ยิ้ว | D16: - | E16: 4322087334 | F16: SCB | G16: =IFERROR(_xlfn.XLOOKUP(F16,K:K,L:L),"") | H16: BM2
A17: 16 | B17: โนรี เต็งโลง | C17: โนรี | D17: 0980670279 | E17: 2182901441 | F17: SCB | G17: =IFERROR(_xlfn.XLOOKUP(F17,K:K,L:L),"") | H17: BM2
A18: 17 | B18: มาติกา โปจีน | D18: - | E18: 2892319976 | F18: SCB | G18: =IFERROR(_xlfn.XLOOKUP(F18,K:K,L:L),"")
A19: 18 | B19: จันทร์วิมล เครือษา | C19: มล | D19: 0858687797 | E19: 3472880181 | F19: SCB | G19: =IFERROR(_xlfn.XLOOKUP(F19,K:K,L:L),"")
A20: 19 | B20: ณัฎฐณิชา เครือแสง | D20: - | E20: 4362076351 | F20: SCB | G20: =IFERROR(_xlfn.XLOOKUP(F20,K:K,L:L),"")
A21: 20 | B21: หทัยชนก อัษดา | D21: - | E21: 4351599641 | F21: SCB | G21: =IFERROR(_xlfn.XLOOKUP(F21,K:K,L:L),"")
A22: 21 | B22: สุรชาติ ดีกล้า | C22: กุ้ง | D22: 0612768766 | E22: 4058661244 | F22: SCB | G22: =IFERROR(_xlfn.XLOOKUP(F22,K:K,L:L),"") | H22: BM1
A23: 22 | B23: สว่าง ศิริมานพ | D23: - | E23: 0659760581 | F23: K-BANK | G23: =IFERROR(_xlfn.XLOOKUP(F23,K:K,L:L),"")
A24: 23 | B24: โยษิตา เขียวคำรพ | C24: จูน | D24: 0639767091 | E24: 0371392831 | F24: K-BANK | G24: =IFERROR(_xlfn.XLOOKUP(F24,K:K,L:L),"") | H24: BM1
A25: 24 | B25: จิรายุ เตชวรกิตติ์ | D25: - | E25: 0391809755 | F25: K-BANK | G25: =IFERROR(_xlfn.XLOOKUP(F25,K:K,L:L),"")
A26: 25 | B26: พีรพงษ์ บุญกล้า | D26: - | E26: 0663486047 | F26: K-BANK | G26: =IFERROR(_xlfn.XLOOKUP(F26,K:K,L:L),"")
A27: 26 | B27: ญาณิศา ยังเรือน | D27: - | E27: 2038243937 | F27: K-BANK | G27: =IFERROR(_xlfn.XLOOKUP(F27,K:K,L:L),"")
A28: 27 | B28: ญาดา กูใหญ่ | D28: - | E28: 1528436168 | F28: K-BANK | G28: =IFERROR(_xlfn.XLOOKUP(F28,K:K,L:L),"")
A29: 28 | B29: ปทิตตา มีทรัพย์ | D29: - | E29: 0918551158 | F29: K-BANK | G29: =IFERROR(_xlfn.XLOOKUP(F29,K:K,L:L),"")
A30: 29 | B30: ธิดารัตน์ บุญกำเนิด | D30: - | E30: 1552655474 | F30: K-BANK | G30: =IFERROR(_xlfn.XLOOKUP(F30,K:K,L:L),"")
A31: 30 | B31: อภิวัฒ์ คงโต | D31: - | E31: 0213893777 | F31: K-BANK | G31: =IFERROR(_xlfn.XLOOKUP(F31,K:K,L:L),"")
A32: 31 | B32: โอภาส สืบสม | D32: - | E32: 7510035863 | F32: BBL | G32: =IFERROR(_xlfn.XLOOKUP(F32,K:K,L:L),"")
A33: 32 | B33: อภิชาติ เปี่ยมจริยกุล | D33: - | E33: 1300909585 | F33: BBL | G33: =IFERROR(_xlfn.XLOOKUP(F33,K:K,L:L),"")
A34: 33 | B34: อรรถกร เปี่ยมจริยกุล | D34: - | E34: 8650680955 | F34: BBL | G34: =IFERROR(_xlfn.XLOOKUP(F34,K:K,L:L),"")
A35: 34 | B35: น้ำทิพย์ คำสุข | C35: อ้อย | D35: 0825088928 | E35: 3330764066 | F35: KTB | G35: =IFERROR(_xlfn.XLOOKUP(F35,K:K,L:L),"")
A36: 35 | B36: ณัฐชา สนทาธร | D36: - | E36: 4883407748 | F36: KTB | G36: =IFERROR(_xlfn.XLOOKUP(F36,K:K,L:L),"")
A37: 36 | B37: นันท์นภัส วงคีรี | D37: - | E37: 4580363620 | F37: KTB | G37: =IFERROR(_xlfn.XLOOKUP(F37,K:K,L:L),"")
A38: 37 | B38: พัชรินทร์ ลุกันทา | D38: - | E38: 7690184278 | F38: KTB | G38: =IFERROR(_xlfn.XLOOKUP(F38,K:K,L:L),"")
A39: 38 | B39: อาชานัย ปานกุล | C39: เป็ก | D39: 0967746948 | E39: 5770449012 | F39: KTB | G39: =IFERROR(_xlfn.XLOOKUP(F39,K:K,L:L),"") | H39: BM1
A40: 39 | B40: กมลลักษณ์ พัดพรม | D40: 0658702122 | E40: 0658702122 | F40: K-BANK | G40: =IFERROR(_xlfn.XLOOKUP(F40,K:K,L:L),"")
...

Sheet Result
A1: PART TIME SUMMARY PAYMENT | E1: =SUBTOTAL(9,E3:E595) | F1: =SUBTOTAL(9,F3:F595) | G1: =SUBTOTAL(9,G3:G595) | H1: =SUBTOTAL(9,H3:H595) | I1: =SUBTOTAL(9,I3:I595) | J1: =SUBTOTAL(9,J3:J595) | K1: =SUBTOTAL(9,K3:K595) | L1: =SUBTOTAL(9,L3:L595) | ... AW1: =SUBTOTAL(9,AW3:AW595) | AX1: =SUM(AX3:AX595)
A2: ลำดับ | B2: ชื่อ - สกุล | C2: ชื่อเล่น | D2: สังกัด | E2: ค่าแรง วันที่ 1 | F2: โอที วันที่ 1 | G2: ค่าแรง วันที่ 2 | H2: โอที วันที่ 2 | I2: ค่าแรง วันที่ 3 | J2: โอที วันที่ 3 | K2: ค่าแรง วันที่ 4 | L2: โอที วันที่ 4 | M2: ค่าแรง วันที่ 5 | N2: โอที วันที่ 5 | O2: ค่าแรง วันที่ 6 | P2: โอที วันที่ 6 | Q2: ค่าแรง วันที่ 7 | R2: โอที วันที่ 7 | S2: ค่าแรง วันที่ 8 | T2: โอที วันที่ 8 | U2: ค่าแรง วันที่ 9 | V2: โอที วันที่ 9 | W2: ค่าแรง วันที่ 10 | X2: โอที วันที่ 10 | Y2: ค่าแรง วันที่ 11 | Z2: โอที วันที่ 11 | AA2: ค่าแรง วันที่ 12 | AB2: โอที วันที่ 12 | AC2: ค่าแรง วันที่ 13 | AD2: โอที วันที่ 13 | AE2: ค่าแรง วันที่ 13 | AF2: โอที วันที่ 13 | AG2: วันที่ 15 | AH2: วันที่ 16 | AI2: วันที่ 17 | AJ2: วันที่ 18 | AK2: วันที่ 19 | AL2: วันที่ 20 | AM2: วันที่ 21 | AN2: วันที่ 22 | AO2: วันที่ 23 | AP2: วันที่ 24 | AQ2: วันที่ 25 | AR2: วันที่ 26 | AS2: วันที่ 27 | AT2: วันที่ 28 | AU2: วันที่ 29 | AV2: วันที่ 30 | AW2: วันที่ 31 | AX2: SUM
A3: 1 | B3: ธนาธิป ควรสำโรง | C3: =IFERROR(VLOOKUP(B3,Members!B:C,2,FALSE),0) | D3: =IFERROR(VLOOKUP(B3,Members!$B:$H,7,FALSE),0) | E3: =IFERROR(VLOOKUP(B3,'วันที่ 1'!$B$8:$AH$103,28,FALSE),0) - IFERROR(VLOOKUP(B3,'วันที่ 1'!$B$8:$AH$103,27,FALSE),0) | F3: =IFERROR(VLOOKUP(C3,'วันที่ 1'!$B$8:$AH$103,27,FALSE),0) | G3: =IFERROR(VLOOKUP(B3,'วันที่ 1'!$B$8:$AH$103,28,FALSE),0)-IFERROR(VLOOKUP(B3,'วันที่ 1'!$B$8:$AH$103,27,FALSE),0) | H3: =IFERROR(VLOOKUP(B3,'วันที่ 1'!$B$8:$AH$103,27,FALSE),0) | I3: =IFERROR(VLOOKUP(B3,'วันที่ 2'!$B$8:$AF$106,28,FALSE),0)-IFERROR(VLOOKUP(B3,'วันที่ 2'!$B$8:$AF$106,27,FALSE),0) | J3: =IFERROR(VLOOKUP(B3,'วันที่ 2'!$B$8:$AF$106,27,FALSE),0) | K3: =IFERROR(VLOOKUP(B3,'วันที่ 3 กะเช้า'!$B$8:$AK$106,28,FALSE),0)-IFERROR(VLOOKUP(B3,'วันที่ 3 กะเช้า'!$B$8:$AK$106,27,FALSE),0) | L3: =IFERROR(VLOOKUP(B3,'วันที่ 3 กะเช้า'!$B$8:$AK$106,27,FALSE),0) | M3: =IFERROR(VLOOKUP(B3,'วันที่ 4 กะเช้า'!$B$8:$AG$107,28,FALSE),0)-IFERROR(VLOOKUP(B3,'วันที่ 4 กะเช้า'!$B$8:$AG$107,27,FALSE),0) | N3: =IFERROR(VLOOKUP(B3,'วันที่ 4 กะเช้า'!$B$8:$AG$107,27,FALSE),0) | O3: =IFERROR(VLOOKUP(B3,'วันที่ 4 กะเช้า'!$B$8:$AH$106,28,FALSE),0)-IFERROR(VLOOKUP(B3,'วันที่ 4 กะเช้า'!$B$8:$AH$106,27,FALSE),0) | P3: =IFERROR(VLOOKUP(B3,'วันที่ 4 กะเช้า'!$B$8:$AH$106,27,FALSE),0) | Q3: =IFERROR(VLOOKUP(B3,'วันที่ 4 กะเช้า'!$B$8:$AH$106,28,FALSE),0)-IFERROR(VLOOKUP(B3,'วันที่ 4 กะเช้า'!$B$8:$AH$106,27,FALSE),0) | R3: =IFERROR(VLOOKUP(B3,'วันที่ 4 กะเช้า'!$B$8:$AH$106,27,FALSE),0) | S3: =IFERROR(VLOOKUP(B3,'วันที่ 5 กะเช้า'!$B$8:$AH$107,28,FALSE),0)-IFERROR(VLOOKUP(B3,'วันที่ 5 กะเช้า'!$B$8:$AH$107,27,FALSE),0) | T3: =IFERROR(VLOOKUP(B3,'วันที่ 5 กะเช้า'!$B$8:$AH$107,27,FALSE),0) | U3: =IFERROR(VLOOKUP(B3,'วันที่ 5 กะดึก'!$B$8:$AH$106,27,FALSE),0) | V3: =IFERROR(VLOOKUP(B3,'วันที่ 5 กะดึก'!$B$8:$AH$106,27,FALSE),0) | W3: =IFERROR(VLOOKUP(B3,'วันที่ 7'!$B$8:$AH$105,28,FALSE),0)-IFERROR(VLOOKUP(B3,'วันที่ 7'!$B$8:$AH$105,27,FALSE),0) | X3: =IFERROR(VLOOKUP(B3,'วันที่ 7'!$B$8:$AH$105,27,FALSE),0) | Y3: =IFERROR(VLOOKUP(B3,'วันที่ 8'!$B$8:$AH$109,28,FALSE),0)-IFERROR(VLOOKUP(B3,'วันที่ 8'!$B$8:$AH$109,27,FALSE),0) | Z3: =IFERROR(VLOOKUP(B3,'วันที่ 8'!$B$8:$AH$109,27,FALSE),0) | AA3: =IFERROR(VLOOKUP(B3,'กะเช้าวันที่ 12'!$B$8:$AC$102,28,FALSE),0)-IFERROR(VLOOKUP(B3,'กะเช้าวันที่ 12'!$B$8:$AC$102,27,FALSE),0) | AB3: =IFERROR(VLOOKUP(B3,'กะเช้าวันที่ 12'!$B$8:$AC$102,27,FALSE),0) | AC3: =IFERROR(VLOOKUP(B3,'กะเช้าวันที่ 14'!$B$8:$AC$104,28,FALSE),0)-IFERROR(VLOOKUP(B3,'กะเช้าวันที่ 14'!$B$8:$AC$104,27,FALSE),0) | AD3: =IFERROR(VLOOKUP(B3,'กะเช้าวันที่ 14'!$B$8:$AC$104,27,FALSE),0) | AE3: =IFERROR(VLOOKUP(B3,'กะดึกวันที่ 13'!$B$8:$AC$105,28,FALSE),0) | AG3: =IFERROR(VLOOKUP(B3,'วันที่ 12'!$B$8:$AH$105,28,FALSE),0) | AH3: =IFERROR(VLOOKUP(B3,'วันที่ 14'!$B$8:$AH$106,28,FALSE),0) | AI3: =IFERROR(VLOOKUP(B3,'วันที่ 15'!$B$8:$AH$106,28,FALSE),0) | AJ3: =IFERROR(VLOOKUP(B3,'วันที่ 16'!$B$8:$AH$105,28,FALSE),0) | AK3: =IFERROR(VLOOKUP(B3,'วันที่ 17'!$B$8:$AH$105,28,FALSE),0) | AL3: =IFERROR(VLOOKUP(B3,'วันที่ 18'!$B$8:$AH$104,28,FALSE),0) | AM3: =IFERROR(VLOOKUP(B3,'วันที่ 19'!$B$8:$AH$106,28,FALSE),0) | AN3: =IFERROR(VLOOKUP(B3,'วันที่ 20'!$B$8:$AH$105,28,FALSE),0) | AO3: =IFERROR(VLOOKUP(B3,'วันที่ 21'!$B$8:$AH$106,28,FALSE),0) | AP3: =IFERROR(VLOOKUP(B3,'วันที่ 22'!$B$8:$AH$105,28,FALSE),0) | AQ3: =IFERROR(VLOOKUP(B3,'วันที่ 23'!$B$8:$AH$107,28,FALSE),0) | AR3: =IFERROR(VLOOKUP(B3,'วันที่ 24'!$B$8:$AH$104,28,FALSE),0) | AS3: =IFERROR(VLOOKUP(B3,'วันที่ 25'!$B$8:$AH$106,28,FALSE),0) | AT3: =IFERROR(VLOOKUP(B3,'วันที่ 26'!$B$8:$AH$105,28,FALSE),0) | AU3: =IFERROR(VLOOKUP(B3,'วันที่ 26'!$B$8:$AH$104,28,FALSE),0) | AV3: =IFERROR(VLOOKUP(B3,'วันที่ 30'!$B$8:$AH$107,28,FALSE),0) | AW3: =IFERROR(VLOOKUP(B3,'วันที่ 31'!$B$8:$AG$105,28,FALSE),0) | AX3: =SUM(E3:AW3)
A4: 2 | B4: ณัฐนรี ภู่พันธ์ | C4: =IFERROR(VLOOKUP(B4,Members!B:C,2,FALSE),0) | D4: =IFERROR(VLOOKUP(B4,Members!$B:$H,7,FALSE),0) | E4: =IFERROR(VLOOKUP(B4,'วันที่ 1'!$B$8:$AH$103,28,FALSE),0) - IFERROR(VLOOKUP(B4,'วันที่ 1'!$B$8:$AH$103,27,FALSE),0) | F4: =IFERROR(VLOOKUP(C4,'วันที่ 1'!$B$8:$AH$103,27,FALSE),0) | G4: =IFERROR(VLOOKUP(B4,'วันที่ 1'!$B$8:$AH$103,28,FALSE),0)-IFERROR(VLOOKUP(B4,'วันที่ 1'!$B$8:$AH$103,27,FALSE),0) | H4: =IFERROR(VLOOKUP(B4,'วันที่ 1'!$B$8:$AH$103,27,FALSE),0) | I4: =IFERROR(VLOOKUP(B4,'วันที่ 2'!$B$8:$AF$106,28,FALSE),0)-IFERROR(VLOOKUP(B4,'วันที่ 2'!$B$8:$AF$106,27,FALSE),0) | J4: =IFERROR(VLOOKUP(B4,'วันที่ 2'!$B$8:$AF$106,27,FALSE),0) | K4: =IFERROR(VLOOKUP(B4,'วันที่ 3 กะเช้า'!$B$8:$AK$106,28,FALSE),0)-IFERROR(VLOOKUP(B4,'วันที่ 3 กะเช้า'!$B$8:$AK$106,27,FALSE),0) | L4: =IFERROR(VLOOKUP(B4,'วันที่ 3 กะเช้า'!$B$8:$AK$106,27,FALSE),0) | M4: =IFERROR(VLOOKUP(B4,'วันที่ 4 กะเช้า'!$B$8:$AG$107,28,FALSE),0)-IFERROR(VLOOKUP(B4,'วันที่ 4 กะเช้า'!$B$8:$AG$107,27,FALSE),0) | N4: =IFERROR(VLOOKUP(B4,'วันที่ 4 กะเช้า'!$B$8:$AG$107,27,FALSE),0) | O4: =IFERROR(VLOOKUP(B4,'วันที่ 4 กะเช้า'!$B$8:$AH$106,28,FALSE),0)-IFERROR(VLOOKUP(B4,'วันที่ 4 กะเช้า'!$B$8:$AH$106,27,FALSE),0) | P4: =IFERROR(VLOOKUP(B4,'วันที่ 4 กะเช้า'!$B$8:$AH$106,27,FALSE),0) | Q4: =IFERROR(VLOOKUP(B4,'วันที่ 4 กะเช้า'!$B$8:$AH$106,28,FALSE),0)-IFERROR(VLOOKUP(B4,'วันที่ 4 กะเช้า'!$B$8:$AH$106,27,FALSE),0) | R4: =IFERROR(VLOOKUP(B4,'วันที่ 4 กะเช้า'!$B$8:$AH$106,27,FALSE),0) | S4: =IFERROR(VLOOKUP(B4,'วันที่ 5 กะเช้า'!$B$8:$AH$107,28,FALSE),0)-IFERROR(VLOOKUP(B4,'วันที่ 5 กะเช้า'!$B$8:$AH$107,27,FALSE),0) | T4: =IFERROR(VLOOKUP(B4,'วันที่ 5 กะเช้า'!$B$8:$AH$107,27,FALSE),0) | U4: =IFERROR(VLOOKUP(B4,'วันที่ 5 กะดึก'!$B$8:$AH$106,27,FALSE),0) | V4: =IFERROR(VLOOKUP(B4,'วันที่ 5 กะดึก'!$B$8:$AH$106,27,FALSE),0) | W4: =IFERROR(VLOOKUP(B4,'วันที่ 7'!$B$8:$AH$105,28,FALSE),0)-IFERROR(VLOOKUP(B4,'วันที่ 7'!$B$8:$AH$105,27,FALSE),0) | X4: =IFERROR(VLOOKUP(B4,'วันที่ 7'!$B$8:$AH$105,27,FALSE),0) | Y4: =IFERROR(VLOOKUP(B4,'วันที่ 8'!$B$8:$AH$109,28,FALSE),0)-IFERROR(VLOOKUP(B4,'วันที่ 8'!$B$8:$AH$109,27,FALSE),0) | Z4: =IFERROR(VLOOKUP(B4,'วันที่ 8'!$B$8:$AH$109,27,FALSE),0) | AA4: =IFERROR(VLOOKUP(B4,'กะเช้าวันที่ 12'!$B$8:$AC$102,28,FALSE),0)-IFERROR(VLOOKUP(B4,'กะเช้าวันที่ 12'!$B$8:$AC$102,27,FALSE),0) | AB4: =IFERROR(VLOOKUP(B4,'กะเช้าวันที่ 12'!$B$8:$AC$102,27,FALSE),0) | AC4: =IFERROR(VLOOKUP(B4,'กะเช้าวันที่ 14'!$B$8:$AC$104,28,FALSE),0)-IFERROR(VLOOKUP(B4,'กะเช้าวันที่ 14'!$B$8:$AC$104,27,FALSE),0) | AD4: =IFERROR(VLOOKUP(B4,'กะเช้าวันที่ 14'!$B$8:$AC$104,27,FALSE),0) | AE4: =IFERROR(VLOOKUP(B4,'กะดึกวันที่ 13'!$B$8:$AC$105,28,FALSE),0) | AG4: =IFERROR(VLOOKUP(B4,'วันที่ 12'!$B$8:$AH$105,28,FALSE),0) | AH4: =IFERROR(VLOOKUP(B4,'วันที่ 14'!$B$8:$AH$106,28,FALSE),0) | AI4: =IFERROR(VLOOKUP(B4,'วันที่ 15'!$B$8:$AH$106,28,FALSE),0) | AJ4: =IFERROR(VLOOKUP(B4,'วันที่ 16'!$B$8:$AH$105,28,FALSE),0) | AK4: =IFERROR(VLOOKUP(B4,'วันที่ 17'!$B$8:$AH$105,28,FALSE),0) | AL4: =IFERROR(VLOOKUP(B4,'วันที่ 18'!$B$8:$AH$104,28,FALSE),0) | AM4: =IFERROR(VLOOKUP(B4,'วันที่ 19'!$B$8:$AH$106,28,FALSE),0) | AN4: =IFERROR(VLOOKUP(B4,'วันที่ 20'!$B$8:$AH$105,28,FALSE),0) | AO4: =IFERROR(VLOOKUP(B4,'วันที่ 21'!$B$8:$AH$106,28,FALSE),0) | AP4: =IFERROR(VLOOKUP(B4,'วันที่ 22'!$B$8:$AH$105,28,FALSE),0) | AQ4: =IFERROR(VLOOKUP(B4,'วันที่ 23'!$B$8:$AH$107,28,FALSE),0) | AR4: =IFERROR(VLOOKUP(B4,'วันที่ 24'!$B$8:$AH$104,28,FALSE),0) | AS4: =IFERROR(VLOOKUP(B4,'วันที่ 25'!$B$8:$AH$106,28,FALSE),0) | AT4: =IFERROR(VLOOKUP(B4,'วันที่ 26'!$B$8:$AH$105,28,FALSE),0) | AU4: =IFERROR(VLOOKUP(B4,'วันที่ 26'!$B$8:$AH$104,28,FALSE),0) | AV4: =IFERROR(VLOOKUP(B4,'วันที่ 30'!$B$8:$AH$107,28,FALSE),0) | AW4: =IFERROR(VLOOKUP(B4,'วันที่ 31'!$B$8:$AG$105,28,FALSE),0) | AX4: =SUM(E4:AW4)
A5: 3 | B5: ปนิดา กะประโคน | C5: =IFERROR(VLOOKUP(B5,Members!B:C,2,FALSE),0) | D5: =IFERROR(VLOOKUP(B5,Members!$B:$H,7,FALSE),0) | E5: =IFERROR(VLOOKUP(B5,'วันที่ 1'!$B$8:$AH$103,28,FALSE),0) - IFERROR(VLOOKUP(B5,'วันที่ 1'!$B$8:$AH$103,27,FALSE),0) | F5: =IFERROR(VLOOKUP(C5,'วันที่ 1'!$B$8:$AH$103,27,FALSE),0) | G5: =IFERROR(VLOOKUP(B5,'วันที่ 1'!$B$8:$AH$103,28,FALSE),0)-IFERROR(VLOOKUP(B5,'วันที่ 1'!$B$8:$AH$103,27,FALSE),0) | H5: =IFERROR(VLOOKUP(B5,'วันที่ 1'!$B$8:$AH$103,27,FALSE),0) | I5: =IFERROR(VLOOKUP(B5,'วันที่ 2'!$B$8:$AF$106,28,FALSE),0)-IFERROR(VLOOKUP(B5,'วันที่ 2'!$B$8:$AF$106,27,FALSE),0) | J5: =IFERROR(VLOOKUP(B5,'วันที่ 2'!$B$8:$AF$106,27,FALSE),0) | K5: =IFERROR(VLOOKUP(B5,'วันที่ 3 กะเช้า'!$B$8:$AK$106,28,FALSE),0)-IFERROR(VLOOKUP(B5,'วันที่ 3 กะเช้า'!$B$8:$AK$106,27,FALSE),0) | L5: =IFERROR(VLOOKUP(B5,'วันที่ 3 กะเช้า'!$B$8:$AK$106,27,FALSE),0) | M5: =IFERROR(VLOOKUP(B5,'วันที่ 4 กะเช้า'!$B$8:$AG$107,28,FALSE),0)-IFERROR(VLOOKUP(B5,'วันที่ 4 กะเช้า'!$B$8:$AG$107,27,FALSE),0) | N5: =IFERROR(VLOOKUP(B5,'วันที่ 4 กะเช้า'!$B$8:$AG$107,27,FALSE),0) | O5: =IFERROR(VLOOKUP(B5,'วันที่ 4 กะเช้า'!$B$8:$AH$106,28,FALSE),0)-IFERROR(VLOOKUP(B5,'วันที่ 4 กะเช้า'!$B$8:$AH$106,27,FALSE),0) | P5: =IFERROR(VLOOKUP(B5,'วันที่ 4 กะเช้า'!$B$8:$AH$106,27,FALSE),0) | Q5: =IFERROR(VLOOKUP(B5,'วันที่ 4 กะเช้า'!$B$8:$AH$106,28,FALSE),0)-IFERROR(VLOOKUP(B5,'วันที่ 4 กะเช้า'!$B$8:$AH$106,27,FALSE),0) | R5: =IFERROR(VLOOKUP(B5,'วันที่ 4 กะเช้า'!$B$8:$AH$106,27,FALSE),0) | S5: =IFERROR(VLOOKUP(B5,'วันที่ 5 กะเช้า'!$B$8:$AH$107,28,FALSE),0)-IFERROR(VLOOKUP(B5,'วันที่ 5 กะเช้า'!$B$8:$AH$107,27,FALSE),0) | T5: =IFERROR(VLOOKUP(B5,'วันที่ 5 กะเช้า'!$B$8:$AH$107,27,FALSE),0) | U5: =IFERROR(VLOOKUP(B5,'วันที่ 5 กะดึก'!$B$8:$AH$106,27,FALSE),0) | V5: =IFERROR(VLOOKUP(B5,'วันที่ 5 กะดึก'!$B$8:$AH$106,27,FALSE),0) | W5: =IFERROR(VLOOKUP(B5,'วันที่ 7'!$B$8:$AH$105,28,FALSE),0)-IFERROR(VLOOKUP(B5,'วันที่ 7'!$B$8:$AH$105,27,FALSE),0) | X5: =IFERROR(VLOOKUP(B5,'วันที่ 7'!$B$8:$AH$105,27,FALSE),0) | Y5: =IFERROR(VLOOKUP(B5,'วันที่ 8'!$B$8:$AH$109,28,FALSE),0)-IFERROR(VLOOKUP(B5,'วันที่ 8'!$B$8:$AH$109,27,FALSE),0) | Z5: =IFERROR(VLOOKUP(B5,'วันที่ 8'!$B$8:$AH$109,27,FALSE),0) | AA5: =IFERROR(VLOOKUP(B5,'กะเช้าวันที่ 12'!$B$8:$AC$102,28,FALSE),0)-IFERROR(VLOOKUP(B5,'กะเช้าวันที่ 12'!$B$8:$AC$102,27,FALSE),0) | AB5: =IFERROR(VLOOKUP(B5,'กะเช้าวันที่ 12'!$B$8:$AC$102,27,FALSE),0) | AC5: =IFERROR(VLOOKUP(B5,'กะเช้าวันที่ 14'!$B$8:$AC$104,28,FALSE),0)-IFERROR(VLOOKUP(B5,'กะเช้าวันที่ 14'!$B$8:$AC$104,27,FALSE),0) | AD5: =IFERROR(VLOOKUP(B5,'กะเช้าวันที่ 14'!$B$8:$AC$104,27,FALSE),0) | AE5: =IFERROR(VLOOKUP(B5,'กะดึกวันที่ 13'!$B$8:$AC$105,28,FALSE),0) | AG5: =IFERROR(VLOOKUP(B5,'วันที่ 12'!$B$8:$AH$105,28,FALSE),0) | AH5: =IFERROR(VLOOKUP(B5,'วันที่ 14'!$B$8:$AH$106,28,FALSE),0) | AI5: =IFERROR(VLOOKUP(B5,'วันที่ 15'!$B$8:$AH$106,28,FALSE),0) | AJ5: =IFERROR(VLOOKUP(B5,'วันที่ 16'!$B$8:$AH$105,28,FALSE),0) | AK5: =IFERROR(VLOOKUP(B5,'วันที่ 17'!$B$8:$AH$105,28,FALSE),0) | AL5: =IFERROR(VLOOKUP(B5,'วันที่ 18'!$B$8:$AH$104,28,FALSE),0) | AM5: =IFERROR(VLOOKUP(B5,'วันที่ 19'!$B$8:$AH$106,28,FALSE),0) | AN5: =IFERROR(VLOOKUP(B5,'วันที่ 20'!$B$8:$AH$105,28,FALSE),0) | AO5: =IFERROR(VLOOKUP(B5,'วันที่ 21'!$B$8:$AH$106,28,FALSE),0) | AP5: =IFERROR(VLOOKUP(B5,'วันที่ 22'!$B$8:$AH$105,28,FALSE),0) | AQ5: =IFERROR(VLOOKUP(B5,'วันที่ 23'!$B$8:$AH$107,28,FALSE),0) | AR5: =IFERROR(VLOOKUP(B5,'วันที่ 24'!$B$8:$AH$104,28,FALSE),0) | AS5: =IFERROR(VLOOKUP(B5,'วันที่ 25'!$B$8:$AH$106,28,FALSE),0) | AT5: =IFERROR(VLOOKUP(B5,'วันที่ 26'!$B$8:$AH$105,28,FALSE),0) | AU5: =IFERROR(VLOOKUP(B5,'วันที่ 26'!$B$8:$AH$104,28,FALSE),0) | AV5: =IFERROR(VLOOKUP(B5,'วันที่ 30'!$B$8:$AH$107,28,FALSE),0) | AW5: =IFERROR(VLOOKUP(B5,'วันที่ 31'!$B$8:$AG$105,28,FALSE),0) | AX5: =SUM(E5:AW5)
A6: 4 | B6: อาชานัย ปานกุล | C6: =IFERROR(VLOOKUP(B6,Members!B:C,2,FALSE),0) | D6: =IFERROR(VLOOKUP(B6,Members!$B:$H,7,FALSE),0) | E6: =IFERROR(VLOOKUP(B6,'วันที่ 1'!$B$8:$AH$103,28,FALSE),0) - IFERROR(VLOOKUP(B6,'วันที่ 1'!$B$8:$AH$103,27,FALSE),0) | F6: =IFERROR(VLOOKUP(C6,'วันที่ 1'!$B$8:$AH$103,27,FALSE),0) | G6: =IFERROR(VLOOKUP(B6,'วันที่ 1'!$B$8:$AH$103,28,FALSE),0)-IFERROR(VLOOKUP(B6,'วันที่ 1'!$B$8:$AH$103,27,FALSE),0) | H6: =IFERROR(VLOOKUP(B6,'วันที่ 1'!$B$8:$AH$103,27,FALSE),0) | I6: =IFERROR(VLOOKUP(B6,'วันที่ 2'!$B$8:$AF$106,28,FALSE),0)-IFERROR(VLOOKUP(B6,'วันที่ 2'!$B$8:$AF$106,27,FALSE),0) | J6: =IFERROR(VLOOKUP(B6,'วันที่ 2'!$B$8:$AF$106,27,FALSE),0) | K6: =IFERROR(VLOOKUP(B6,'วันที่ 3 กะเช้า'!$B$8:$AK$106,28,FALSE),0)-IFERROR(VLOOKUP(B6,'วันที่ 3 กะเช้า'!$B$8:$AK$106,27,FALSE),0) | L6: =IFERROR(VLOOKUP(B6,'วันที่ 3 กะเช้า'!$B$8:$AK$106,27,FALSE),0) | M6: =IFERROR(VLOOKUP(B6,'วันที่ 4 กะเช้า'!$B$8:$AG$107,28,FALSE),0)-IFERROR(VLOOKUP(B6,'วันที่ 4 กะเช้า'!$B$8:$AG$107,27,FALSE),0) | N6: =IFERROR(VLOOKUP(B6,'วันที่ 4 กะเช้า'!$B$8:$AG$107,27,FALSE),0) | O6: =IFERROR(VLOOKUP(B6,'วันที่ 4 กะเช้า'!$B$8:$AH$106,28,FALSE),0)-IFERROR(VLOOKUP(B6,'วันที่ 4 กะเช้า'!$B$8:$AH$106,27,FALSE),0) | P6: =IFERROR(VLOOKUP(B6,'วันที่ 4 กะเช้า'!$B$8:$AH$106,27,FALSE),0) | Q6: =IFERROR(VLOOKUP(B6,'วันที่ 4 กะเช้า'!$B$8:$AH$106,28,FALSE),0)-IFERROR(VLOOKUP(B6,'วันที่ 4 กะเช้า'!$B$8:$AH$106,27,FALSE),0) | R6: =IFERROR(VLOOKUP(B6,'วันที่ 4 กะเช้า'!$B$8:$AH$106,27,FALSE),0) | S6: =IFERROR(VLOOKUP(B6,'วันที่ 5 กะเช้า'!$B$8:$AH$107,28,FALSE),0)-IFERROR(VLOOKUP(B6,'วันที่ 5 กะเช้า'!$B$8:$AH$107,27,FALSE),0) | T6: =IFERROR(VLOOKUP(B6,'วันที่ 5 กะเช้า'!$B$8:$AH$107,27,FALSE),0) | U6: =IFERROR(VLOOKUP(B6,'วันที่ 5 กะดึก'!$B$8:$AH$106,27,FALSE),0) | V6: =IFERROR(VLOOKUP(B6,'วันที่ 5 กะดึก'!$B$8:$AH$106,27,FALSE),0) | W6: =IFERROR(VLOOKUP(B6,'วันที่ 7'!$B$8:$AH$105,28,FALSE),0)-IFERROR(VLOOKUP(B6,'วันที่ 7'!$B$8:$AH$105,27,FALSE),0) | X6: =IFERROR(VLOOKUP(B6,'วันที่ 7'!$B$8:$AH$105,27,FALSE),0) | Y6: =IFERROR(VLOOKUP(B6,'วันที่ 8'!$B$8:$AH$109,28,FALSE),0)-IFERROR(VLOOKUP(B6,'วันที่ 8'!$B$8:$AH$109,27,FALSE),0) | Z6: =IFERROR(VLOOKUP(B6,'วันที่ 8'!$B$8:$AH$109,27,FALSE),0) | AA6: =IFERROR(VLOOKUP(B6,'กะเช้าวันที่ 12'!$B$8:$AC$102,28,FALSE),0)-IFERROR(VLOOKUP(B6,'กะเช้าวันที่ 12'!$B$8:$AC$102,27,FALSE),0) | AB6: =IFERROR(VLOOKUP(B6,'กะเช้าวันที่ 12'!$B$8:$AC$102,27,FALSE),0) | AC6: =IFERROR(VLOOKUP(B6,'กะเช้าวันที่ 14'!$B$8:$AC$104,28,FALSE),0)-IFERROR(VLOOKUP(B6,'กะเช้าวันที่ 14'!$B$8:$AC$104,27,FALSE),0) | AD6: =IFERROR(VLOOKUP(B6,'กะเช้าวันที่ 14'!$B$8:$AC$104,27,FALSE),0) | AE6: =IFERROR(VLOOKUP(B6,'กะดึกวันที่ 13'!$B$8:$AC$105,28,FALSE),0) | AG6: =IFERROR(VLOOKUP(B6,'วันที่ 12'!$B$8:$AH$105,28,FALSE),0) | AH6: =IFERROR(VLOOKUP(B6,'วันที่ 14'!$B$8:$AH$106,28,FALSE),0) | AI6: =IFERROR(VLOOKUP(B6,'วันที่ 15'!$B$8:$AH$106,28,FALSE),0) | AJ6: =IFERROR(VLOOKUP(B6,'วันที่ 16'!$B$8:$AH$105,28,FALSE),0) | AK6: =IFERROR(VLOOKUP(B6,'วันที่ 17'!$B$8:$AH$105,28,FALSE),0) | AL6: =IFERROR(VLOOKUP(B6,'วันที่ 18'!$B$8:$AH$104,28,FALSE),0) | AM6: =IFERROR(VLOOKUP(B6,'วันที่ 19'!$B$8:$AH$106,28,FALSE),0) | AN6: =IFERROR(VLOOKUP(B6,'วันที่ 20'!$B$8:$AH$105,28,FALSE),0) | AO6: =IFERROR(VLOOKUP(B6,'วันที่ 21'!$B$8:$AH$106,28,FALSE),0) | AP6: =IFERROR(VLOOKUP(B6,'วันที่ 22'!$B$8:$AH$105,28,FALSE),0) | AQ6: =IFERROR(VLOOKUP(B6,'วันที่ 23'!$B$8:$AH$107,28,FALSE),0) | AR6: =IFERROR(VLOOKUP(B6,'วันที่ 24'!$B$8:$AH$104,28,FALSE),0) | AS6: =IFERROR(VLOOKUP(B6,'วันที่ 25'!$B$8:$AH$106,28,FALSE),0) | AT6: =IFERROR(VLOOKUP(B6,'วันที่ 26'!$B$8:$AH$105,28,FALSE),0) | AU6: =IFERROR(VLOOKUP(B6,'วันที่ 26'!$B$8:$AH$104,28,FALSE),0) | AV6: =IFERROR(VLOOKUP(B6,'วันที่ 30'!$B$8:$AH$107,28,FALSE),0) | AW6: =IFERROR(VLOOKUP(B6,'วันที่ 31'!$B$8:$AG$105,28,FALSE),0) | AX6: =SUM(E6:AW6)
A7: 5 | B7: กัญญาณัฐ ลือธิสาร | C7: =IFERROR(VLOOKUP(B7,Members!B:C,2,FALSE),0) | D7: =IFERROR(VLOOKUP(B7,Members!$B:$H,7,FALSE),0) | E7: =IFERROR(VLOOKUP(B7,'วันที่ 1'!$B$8:$AH$103,28,FALSE),0) - IFERROR(VLOOKUP(B7,'วันที่ 1'!$B$8:$AH$103,27,FALSE),0) | F7: =IFERROR(VLOOKUP(C7,'วันที่ 1'!$B$8:$AH$103,27,FALSE),0) | G7: =IFERROR(VLOOKUP(B7,'วันที่ 1'!$B$8:$AH$103,28,FALSE),0)-IFERROR(VLOOKUP(B7,'วันที่ 1'!$B$8:$AH$103,27,FALSE),0) | H7: =IFERROR(VLOOKUP(B7,'วันที่ 1'!$B$8:$AH$103,27,FALSE),0) | I7: =IFERROR(VLOOKUP(B7,'วันที่ 2'!$B$8:$AF$106,28,FALSE),0)-IFERROR(VLOOKUP(B7,'วันที่ 2'!$B$8:$AF$106,27,FALSE),0) | J7: =IFERROR(VLOOKUP(B7,'วันที่ 2'!$B$8:$AF$106,27,FALSE),0) | K7: =IFERROR(VLOOKUP(B7,'วันที่ 3 กะเช้า'!$B$8:$AK$106,28,FALSE),0)-IFERROR(VLOOKUP(B7,'วันที่ 3 กะเช้า'!$B$8:$AK$106,27,FALSE),0) | L7: =IFERROR(VLOOKUP(B7,'วันที่ 3 กะเช้า'!$B$8:$AK$106,27,FALSE),0) | M7: =IFERROR(VLOOKUP(B7,'วันที่ 4 กะเช้า'!$B$8:$AG$107,28,FALSE),0)-IFERROR(VLOOKUP(B7,'วันที่ 4 กะเช้า'!$B$8:$AG$107,27,FALSE),0) | N7: =IFERROR(VLOOKUP(B7,'วันที่ 4 กะเช้า'!$B$8:$AG$107,27,FALSE),0) | O7: =IFERROR(VLOOKUP(B7,'วันที่ 4 กะเช้า'!$B$8:$AH$106,28,FALSE),0)-IFERROR(VLOOKUP(B7,'วันที่ 4 กะเช้า'!$B$8:$AH$106,27,FALSE),0) | P7: =IFERROR(VLOOKUP(B7,'วันที่ 4 กะเช้า'!$B$8:$AH$106,27,FALSE),0) | Q7: =IFERROR(VLOOKUP(B7,'วันที่ 4 กะเช้า'!$B$8:$AH$106,28,FALSE),0)-IFERROR(VLOOKUP(B7,'วันที่ 4 กะเช้า'!$B$8:$AH$106,27,FALSE),0) | R7: =IFERROR(VLOOKUP(B7,'วันที่ 4 กะเช้า'!$B$8:$AH$106,27,FALSE),0) | S7: =IFERROR(VLOOKUP(B7,'วันที่ 5 กะเช้า'!$B$8:$AH$107,28,FALSE),0)-IFERROR(VLOOKUP(B7,'วันที่ 5 กะเช้า'!$B$8:$AH$107,27,FALSE),0) | T7: =IFERROR(VLOOKUP(B7,'วันที่ 5 กะเช้า'!$B$8:$AH$107,27,FALSE),0) | U7: =IFERROR(VLOOKUP(B7,'วันที่ 5 กะดึก'!$B$8:$AH$106,27,FALSE),0) | V7: =IFERROR(VLOOKUP(B7,'วันที่ 5 กะดึก'!$B$8:$AH$106,27,FALSE),0) | W7: =IFERROR(VLOOKUP(B7,'วันที่ 7'!$B$8:$AH$105,28,FALSE),0)-IFERROR(VLOOKUP(B7,'วันที่ 7'!$B$8:$AH$105,27,FALSE),0) | X7: =IFERROR(VLOOKUP(B7,'วันที่ 7'!$B$8:$AH$105,27,FALSE),0) | Y7: =IFERROR(VLOOKUP(B7,'วันที่ 8'!$B$8:$AH$109,28,FALSE),0)-IFERROR(VLOOKUP(B7,'วันที่ 8'!$B$8:$AH$109,27,FALSE),0) | Z7: =IFERROR(VLOOKUP(B7,'วันที่ 8'!$B$8:$AH$109,27,FALSE),0) | AA7: =IFERROR(VLOOKUP(B7,'กะเช้าวันที่ 12'!$B$8:$AC$102,28,FALSE),0)-IFERROR(VLOOKUP(B7,'กะเช้าวันที่ 12'!$B$8:$AC$102,27,FALSE),0) | AB7: =IFERROR(VLOOKUP(B7,'กะเช้าวันที่ 12'!$B$8:$AC$102,27,FALSE),0) | AC7: =IFERROR(VLOOKUP(B7,'กะเช้าวันที่ 14'!$B$8:$AC$104,28,FALSE),0)-IFERROR(VLOOKUP(B7,'กะเช้าวันที่ 14'!$B$8:$AC$104,27,FALSE),0) | AD7: =IFERROR(VLOOKUP(B7,'กะเช้าวันที่ 14'!$B$8:$AC$104,27,FALSE),0) | AE7: =IFERROR(VLOOKUP(B7,'กะดึกวันที่ 13'!$B$8:$AC$105,28,FALSE),0) | AG7: =IFERROR(VLOOKUP(B7,'วันที่ 12'!$B$8:$AH$105,28,FALSE),0) | AH7: =IFERROR(VLOOKUP(B7,'วันที่ 14'!$B$8:$AH$106,28,FALSE),0) | AI7: =IFERROR(VLOOKUP(B7,'วันที่ 15'!$B$8:$AH$106,28,FALSE),0) | AJ7: =IFERROR(VLOOKUP(B7,'วันที่ 16'!$B$8:$AH$105,28,FALSE),0) | AK7: =IFERROR(VLOOKUP(B7,'วันที่ 17'!$B$8:$AH$105,28,FALSE),0) | AL7: =IFERROR(VLOOKUP(B7,'วันที่ 18'!$B$8:$AH$104,28,FALSE),0) | AM7: =IFERROR(VLOOKUP(B7,'วันที่ 19'!$B$8:$AH$106,28,FALSE),0) | AN7: =IFERROR(VLOOKUP(B7,'วันที่ 20'!$B$8:$AH$105,28,FALSE),0) | AO7: =IFERROR(VLOOKUP(B7,'วันที่ 21'!$B$8:$AH$106,28,FALSE),0) | AP7: =IFERROR(VLOOKUP(B7,'วันที่ 22'!$B$8:$AH$105,28,FALSE),0) | AQ7: =IFERROR(VLOOKUP(B7,'วันที่ 23'!$B$8:$AH$107,28,FALSE),0) | AR7: =IFERROR(VLOOKUP(B7,'วันที่ 24'!$B$8:$AH$104,28,FALSE),0) | AS7: =IFERROR(VLOOKUP(B7,'วันที่ 25'!$B$8:$AH$106,28,FALSE),0) | AT7: =IFERROR(VLOOKUP(B7,'วันที่ 26'!$B$8:$AH$105,28,FALSE),0) | AU7: =IFERROR(VLOOKUP(B7,'วันที่ 26'!$B$8:$AH$104,28,FALSE),0) | AV7: =IFERROR(VLOOKUP(B7,'วันที่ 30'!$B$8:$AH$107,28,FALSE),0) | AW7: =IFERROR(VLOOKUP(B7,'วันที่ 31'!$B$8:$AG$105,28,FALSE),0) | AX7: =SUM(E7:AW7)
A8: 6 | B8: จุฑามาศ พลเยี่ยม | C8: =IFERROR(VLOOKUP(B8,Members!B:C,2,FALSE),0) | D8: =IFERROR(VLOOKUP(B8,Members!$B:$H,7,FALSE),0) | E8: =IFERROR(VLOOKUP(B8,'วันที่ 1'!$B$8:$AH$103,28,FALSE),0) - IFERROR(VLOOKUP(B8,'วันที่ 1'!$B$8:$AH$103,27,FALSE),0) | F8: =IFERROR(VLOOKUP(C8,'วันที่ 1'!$B$8:$AH$103,27,FALSE),0) | G8: =IFERROR(VLOOKUP(B8,'วันที่ 1'!$B$8:$AH$103,28,FALSE),0)-IFERROR(VLOOKUP(B8,'วันที่ 1'!$B$8:$AH$103,27,FALSE),0) | H8: =IFERROR(VLOOKUP(B8,'วันที่ 1'!$B$8:$AH$103,27,FALSE),0) | I8: =IFERROR(VLOOKUP(B8,'วันที่ 2'!$B$8:$AF$106,28,FALSE),0)-IFERROR(VLOOKUP(B8,'วันที่ 2'!$B$8:$AF$106,27,FALSE),0) | J8: =IFERROR(VLOOKUP(B8,'วันที่ 2'!$B$8:$AF$106,27,FALSE),0) | K8: =IFERROR(VLOOKUP(B8,'วันที่ 3 กะเช้า'!$B$8:$AK$106,28,FALSE),0)-IFERROR(VLOOKUP(B8,'วันที่ 3 กะเช้า'!$B$8:$AK$106,27,FALSE),0) | L8: =IFERROR(VLOOKUP(B8,'วันที่ 3 กะเช้า'!$B$8:$AK$106,27,FALSE),0) | M8: =IFERROR(VLOOKUP(B8,'วันที่ 4 กะเช้า'!$B$8:$AG$107,28,FALSE),0)-IFERROR(VLOOKUP(B8,'วันที่ 4 กะเช้า'!$B$8:$AG$107,27,FALSE),0) | N8: =IFERROR(VLOOKUP(B8,'วันที่ 4 กะเช้า'!$B$8:$AG$107,27,FALSE),0) | O8: =IFERROR(VLOOKUP(B8,'วันที่ 4 กะเช้า'!$B$8:$AH$106,28,FALSE),0)-IFERROR(VLOOKUP(B8,'วันที่ 4 กะเช้า'!$B$8:$AH$106,27,FALSE),0) | P8: =IFERROR(VLOOKUP(B8,'วันที่ 4 กะเช้า'!$B$8:$AH$106,27,FALSE),0) | Q8: =IFERROR(VLOOKUP(B8,'วันที่ 4 กะเช้า'!$B$8:$AH$106,28,FALSE),0)-IFERROR(VLOOKUP(B8,'วันที่ 4 กะเช้า'!$B$8:$AH$106,27,FALSE),0) | R8: =IFERROR(VLOOKUP(B8,'วันที่ 4 กะเช้า'!$B$8:$AH$106,27,FALSE),0) | S8: =IFERROR(VLOOKUP(B8,'วันที่ 5 กะเช้า'!$B$8:$AH$107,28,FALSE),0)-IFERROR(VLOOKUP(B8,'วันที่ 5 กะเช้า'!$B$8:$AH$107,27,FALSE),0) | T8: =IFERROR(VLOOKUP(B8,'วันที่ 5 กะเช้า'!$B$8:$AH$107,27,FALSE),0) | U8: =IFERROR(VLOOKUP(B8,'วันที่ 5 กะดึก'!$B$8:$AH$106,27,FALSE),0) | V8: =IFERROR(VLOOKUP(B8,'วันที่ 5 กะดึก'!$B$8:$AH$106,27,FALSE),0) | W8: =IFERROR(VLOOKUP(B8,'วันที่ 7'!$B$8:$AH$105,28,FALSE),0)-IFERROR(VLOOKUP(B8,'วันที่ 7'!$B$8:$AH$105,27,FALSE),0) | X8: =IFERROR(VLOOKUP(B8,'วันที่ 7'!$B$8:$AH$105,27,FALSE),0) | Y8: =IFERROR(VLOOKUP(B8,'วันที่ 8'!$B$8:$AH$109,28,FALSE),0)-IFERROR(VLOOKUP(B8,'วันที่ 8'!$B$8:$AH$109,27,FALSE),0) | Z8: =IFERROR(VLOOKUP(B8,'วันที่ 8'!$B$8:$AH$109,27,FALSE),0) | AA8: =IFERROR(VLOOKUP(B8,'กะเช้าวันที่ 12'!$B$8:$AC$102,28,FALSE),0)-IFERROR(VLOOKUP(B8,'กะเช้าวันที่ 12'!$B$8:$AC$102,27,FALSE),0) | AB8: =IFERROR(VLOOKUP(B8,'กะเช้าวันที่ 12'!$B$8:$AC$102,27,FALSE),0) | AC8: =IFERROR(VLOOKUP(B8,'กะเช้าวันที่ 14'!$B$8:$AC$104,28,FALSE),0)-IFERROR(VLOOKUP(B8,'กะเช้าวันที่ 14'!$B$8:$AC$104,27,FALSE),0) | AD8: =IFERROR(VLOOKUP(B8,'กะเช้าวันที่ 14'!$B$8:$AC$104,27,FALSE),0) | AE8: =IFERROR(VLOOKUP(B8,'กะดึกวันที่ 13'!$B$8:$AC$105,28,FALSE),0) | AG8: =IFERROR(VLOOKUP(B8,'วันที่ 12'!$B$8:$AH$105,28,FALSE),0) | AH8: =IFERROR(VLOOKUP(B8,'วันที่ 14'!$B$8:$AH$106,28,FALSE),0) | AI8: =IFERROR(VLOOKUP(B8,'วันที่ 15'!$B$8:$AH$106,28,FALSE),0) | AJ8: =IFERROR(VLOOKUP(B8,'วันที่ 16'!$B$8:$AH$105,28,FALSE),0) | AK8: =IFERROR(VLOOKUP(B8,'วันที่ 17'!$B$8:$AH$105,28,FALSE),0) | AL8: =IFERROR(VLOOKUP(B8,'วันที่ 18'!$B$8:$AH$104,28,FALSE),0) | AM8: =IFERROR(VLOOKUP(B8,'วันที่ 19'!$B$8:$AH$106,28,FALSE),0) | AN8: =IFERROR(VLOOKUP(B8,'วันที่ 20'!$B$8:$AH$105,28,FALSE),0) | AO8: =IFERROR(VLOOKUP(B8,'วันที่ 21'!$B$8:$AH$106,28,FALSE),0) | AP8: =IFERROR(VLOOKUP(B8,'วันที่ 22'!$B$8:$AH$105,28,FALSE),0) | AQ8: =IFERROR(VLOOKUP(B8,'วันที่ 23'!$B$8:$AH$107,28,FALSE),0) | AR8: =IFERROR(VLOOKUP(B8,'วันที่ 24'!$B$8:$AH$104,28,FALSE),0) | AS8: =IFERROR(VLOOKUP(B8,'วันที่ 25'!$B$8:$AH$106,28,FALSE),0) | AT8: =IFERROR(VLOOKUP(B8,'วันที่ 26'!$B$8:$AH$105,28,FALSE),0) | AU8: =IFERROR(VLOOKUP(B8,'วันที่ 26'!$B$8:$AH$104,28,FALSE),0) | AV8: =IFERROR(VLOOKUP(B8,'วันที่ 30'!$B$8:$AH$107,28,FALSE),0) | AW8: =IFERROR(VLOOKUP(B8,'วันที่ 31'!$B$8:$AG$105,28,FALSE),0) | AX8: =SUM(E8:AW8)
A9: 7 | B9: เกณิกา ฐาณัตตระกูล | C9: =IFERROR(VLOOKUP(B9,Members!B:C,2,FALSE),0) | D9: =IFERROR(VLOOKUP(B9,Members!$B:$H,7,FALSE),0) | E9: =IFERROR(VLOOKUP(B9,'วันที่ 1'!$B$8:$AH$103,28,FALSE),0) - IFERROR(VLOOKUP(B9,'วันที่ 1'!$B$8:$AH$103,27,FALSE),0) | F9: =IFERROR(VLOOKUP(C9,'วันที่ 1'!$B$8:$AH$103,27,FALSE),0) | G9: =IFERROR(VLOOKUP(B9,'วันที่ 1'!$B$8:$AH$103,28,FALSE),0)-IFERROR(VLOOKUP(B9,'วันที่ 1'!$B$8:$AH$103,27,FALSE),0) | H9: =IFERROR(VLOOKUP(B9,'วันที่ 1'!$B$8:$AH$103,27,FALSE),0) | I9: =IFERROR(VLOOKUP(B9,'วันที่ 2'!$B$8:$AF$106,28,FALSE),0)-IFERROR(VLOOKUP(B9,'วันที่ 2'!$B$8:$AF$106,27,FALSE),0) | J9: =IFERROR(VLOOKUP(B9,'วันที่ 2'!$B$8:$AF$106,27,FALSE),0) | K9: =IFERROR(VLOOKUP(B9,'วันที่ 3 กะเช้า'!$B$8:$AK$106,28,FALSE),0)-IFERROR(VLOOKUP(B9,'วันที่ 3 กะเช้า'!$B$8:$AK$106,27,FALSE),0) | L9: =IFERROR(VLOOKUP(B9,'วันที่ 3 กะเช้า'!$B$8:$AK$106,27,FALSE),0) | M9: =IFERROR(VLOOKUP(B9,'วันที่ 4 กะเช้า'!$B$8:$AG$107,28,FALSE),0)-IFERROR(VLOOKUP(B9,'วันที่ 4 กะเช้า'!$B$8:$AG$107,27,FALSE),0) | N9: =IFERROR(VLOOKUP(B9,'วันที่ 4 กะเช้า'!$B$8:$AG$107,27,FALSE),0) | O9: =IFERROR(VLOOKUP(B9,'วันที่ 4 กะเช้า'!$B$8:$AH$106,28,FALSE),0)-IFERROR(VLOOKUP(B9,'วันที่ 4 กะเช้า'!$B$8:$AH$106,27,FALSE),0) | P9: =IFERROR(VLOOKUP(B9,'วันที่ 4 กะเช้า'!$B$8:$AH$106,27,FALSE),0) | Q9: =IFERROR(VLOOKUP(B9,'วันที่ 4 กะเช้า'!$B$8:$AH$106,28,FALSE),0)-IFERROR(VLOOKUP(B9,'วันที่ 4 กะเช้า'!$B$8:$AH$106,27,FALSE),0) | R9: =IFERROR(VLOOKUP(B9,'วันที่ 4 กะเช้า'!$B$8:$AH$106,27,FALSE),0) | S9: =IFERROR(VLOOKUP(B9,'วันที่ 5 กะเช้า'!$B$8:$AH$107,28,FALSE),0)-IFERROR(VLOOKUP(B9,'วันที่ 5 กะเช้า'!$B$8:$AH$107,27,FALSE),0) | T9: =IFERROR(VLOOKUP(B9,'วันที่ 5 กะเช้า'!$B$8:$AH$107,27,FALSE),0) | U9: =IFERROR(VLOOKUP(B9,'วันที่ 5 กะดึก'!$B$8:$AH$106,27,FALSE),0) | V9: =IFERROR(VLOOKUP(B9,'วันที่ 5 กะดึก'!$B$8:$AH$106,27,FALSE),0) | W9: =IFERROR(VLOOKUP(B9,'วันที่ 7'!$B$8:$AH$105,28,FALSE),0)-IFERROR(VLOOKUP(B9,'วันที่ 7'!$B$8:$AH$105,27,FALSE),0) | X9: =IFERROR(VLOOKUP(B9,'วันที่ 7'!$B$8:$AH$105,27,FALSE),0) | Y9: =IFERROR(VLOOKUP(B9,'วันที่ 8'!$B$8:$AH$109,28,FALSE),0)-IFERROR(VLOOKUP(B9,'วันที่ 8'!$B$8:$AH$109,27,FALSE),0) | Z9: =IFERROR(VLOOKUP(B9,'วันที่ 8'!$B$8:$AH$109,27,FALSE),0) | AA9: =IFERROR(VLOOKUP(B9,'กะเช้าวันที่ 12'!$B$8:$AC$102,28,FALSE),0)-IFERROR(VLOOKUP(B9,'กะเช้าวันที่ 12'!$B$8:$AC$102,27,FALSE),0) | AB9: =IFERROR(VLOOKUP(B9,'กะเช้าวันที่ 12'!$B$8:$AC$102,27,FALSE),0) | AC9: =IFERROR(VLOOKUP(B9,'กะเช้าวันที่ 14'!$B$8:$AC$104,28,FALSE),0)-IFERROR(VLOOKUP(B9,'กะเช้าวันที่ 14'!$B$8:$AC$104,27,FALSE),0) | AD9: =IFERROR(VLOOKUP(B9,'กะเช้าวันที่ 14'!$B$8:$AC$104,27,FALSE),0) | AE9: =IFERROR(VLOOKUP(B9,'กะดึกวันที่ 13'!$B$8:$AC$105,28,FALSE),0) | AG9: =IFERROR(VLOOKUP(B9,'วันที่ 12'!$B$8:$AH$105,28,FALSE),0) | AH9: =IFERROR(VLOOKUP(B9,'วันที่ 14'!$B$8:$AH$106,28,FALSE),0) | AI9: =IFERROR(VLOOKUP(B9,'วันที่ 15'!$B$8:$AH$106,28,FALSE),0) | AJ9: =IFERROR(VLOOKUP(B9,'วันที่ 16'!$B$8:$AH$105,28,FALSE),0) | AK9: =IFERROR(VLOOKUP(B9,'วันที่ 17'!$B$8:$AH$105,28,FALSE),0) | AL9: =IFERROR(VLOOKUP(B9,'วันที่ 18'!$B$8:$AH$104,28,FALSE),0) | AM9: =IFERROR(VLOOKUP(B9,'วันที่ 19'!$B$8:$AH$106,28,FALSE),0) | AN9: =IFERROR(VLOOKUP(B9,'วันที่ 20'!$B$8:$AH$105,28,FALSE),0) | AO9: =IFERROR(VLOOKUP(B9,'วันที่ 21'!$B$8:$AH$106,28,FALSE),0) | AP9: =IFERROR(VLOOKUP(B9,'วันที่ 22'!$B$8:$AH$105,28,FALSE),0) | AQ9: =IFERROR(VLOOKUP(B9,'วันที่ 23'!$B$8:$AH$107,28,FALSE),0) | AR9: =IFERROR(VLOOKUP(B9,'วันที่ 24'!$B$8:$AH$104,28,FALSE),0) | AS9: =IFERROR(VLOOKUP(B9,'วันที่ 25'!$B$8:$AH$106,28,FALSE),0) | AT9: =IFERROR(VLOOKUP(B9,'วันที่ 26'!$B$8:$AH$105,28,FALSE),0) | AU9: =IFERROR(VLOOKUP(B9,'วันที่ 26'!$B$8:$AH$104,28,FALSE),0) | AV9: =IFERROR(VLOOKUP(B9,'วันที่ 30'!$B$8:$AH$107,28,FALSE),0) | AW9: =IFERROR(VLOOKUP(B9,'วันที่ 31'!$B$8:$AG$105,28,FALSE),0) | AX9: =SUM(E9:AW9)
A10: 8 | B10: อิสรศักดิ์ เวยสาร | C10: =IFERROR(VLOOKUP(B10,Members!B:C,2,FALSE),0) | D10: =IFERROR(VLOOKUP(B10,Members!$B:$H,7,FALSE),0) | E10: =IFERROR(VLOOKUP(B10,'วันที่ 1'!$B$8:$AH$103,28,FALSE),0) - IFERROR(VLOOKUP(B10,'วันที่ 1'!$B$8:$AH$103,27,FALSE),0) | F10: =IFERROR(VLOOKUP(C10,'วันที่ 1'!$B$8:$AH$103,27,FALSE),0) | G10: =IFERROR(VLOOKUP(B10,'วันที่ 1'!$B$8:$AH$103,28,FALSE),0)-IFERROR(VLOOKUP(B10,'วันที่ 1'!$B$8:$AH$103,27,FALSE),0) | H10: =IFERROR(VLOOKUP(B10,'วันที่ 1'!$B$8:$AH$103,27,FALSE),0) | I10: =IFERROR(VLOOKUP(B10,'วันที่ 2'!$B$8:$AF$106,28,FALSE),0)-IFERROR(VLOOKUP(B10,'วันที่ 2'!$B$8:$AF$106,27,FALSE),0) | J10: =IFERROR(VLOOKUP(B10,'วันที่ 2'!$B$8:$AF$106,27,FALSE),0) | K10: =IFERROR(VLOOKUP(B10,'วันที่ 3 กะเช้า'!$B$8:$AK$106,28,FALSE),0)-IFERROR(VLOOKUP(B10,'วันที่ 3 กะเช้า'!$B$8:$AK$106,27,FALSE),0) | L10: =IFERROR(VLOOKUP(B10,'วันที่ 3 กะเช้า'!$B$8:$AK$106,27,FALSE),0) | M10: =IFERROR(VLOOKUP(B10,'วันที่ 4 กะเช้า'!$B$8:$AG$107,28,FALSE),0)-IFERROR(VLOOKUP(B10,'วันที่ 4 กะเช้า'!$B$8:$AG$107,27,FALSE),0) | N10: =IFERROR(VLOOKUP(B10,'วันที่ 4 กะเช้า'!$B$8:$AG$107,27,FALSE),0) | O10: =IFERROR(VLOOKUP(B10,'วันที่ 4 กะเช้า'!$B$8:$AH$106,28,FALSE),0)-IFERROR(VLOOKUP(B10,'วันที่ 4 กะเช้า'!$B$8:$AH$106,27,FALSE),0) | P10: =IFERROR(VLOOKUP(B10,'วันที่ 4 กะเช้า'!$B$8:$AH$106,27,FALSE),0) | Q10: =IFERROR(VLOOKUP(B10,'วันที่ 4 กะเช้า'!$B$8:$AH$106,28,FALSE),0)-IFERROR(VLOOKUP(B10,'วันที่ 4 กะเช้า'!$B$8:$AH$106,27,FALSE),0) | R10: =IFERROR(VLOOKUP(B10,'วันที่ 4 กะเช้า'!$B$8:$AH$106,27,FALSE),0) | S10: =IFERROR(VLOOKUP(B10,'วันที่ 5 กะเช้า'!$B$8:$AH$107,28,FALSE),0)-IFERROR(VLOOKUP(B10,'วันที่ 5 กะเช้า'!$B$8:$AH$107,27,FALSE),0) | T10: =IFERROR(VLOOKUP(B10,'วันที่ 5 กะเช้า'!$B$8:$AH$107,27,FALSE),0) | U10: =IFERROR(VLOOKUP(B10,'วันที่ 5 กะดึก'!$B$8:$AH$106,27,FALSE),0) | V10: =IFERROR(VLOOKUP(B10,'วันที่ 5 กะดึก'!$B$8:$AH$106,27,FALSE),0) | W10: =IFERROR(VLOOKUP(B10,'วันที่ 7'!$B$8:$AH$105,28,FALSE),0)-IFERROR(VLOOKUP(B10,'วันที่ 7'!$B$8:$AH$105,27,FALSE),0) | X10: =IFERROR(VLOOKUP(B10,'วันที่ 7'!$B$8:$AH$105,27,FALSE),0) | Y10: =IFERROR(VLOOKUP(B10,'วันที่ 8'!$B$8:$AH$109,28,FALSE),0)-IFERROR(VLOOKUP(B10,'วันที่ 8'!$B$8:$AH$109,27,FALSE),0) | Z10: =IFERROR(VLOOKUP(B10,'วันที่ 8'!$B$8:$AH$109,27,FALSE),0) | AA10: =IFERROR(VLOOKUP(B10,'กะเช้าวันที่ 12'!$B$8:$AC$102,28,FALSE),0)-IFERROR(VLOOKUP(B10,'กะเช้าวันที่ 12'!$B$8:$AC$102,27,FALSE),0) | AB10: =IFERROR(VLOOKUP(B10,'กะเช้าวันที่ 12'!$B$8:$AC$102,27,FALSE),0) | AC10: =IFERROR(VLOOKUP(B10,'กะเช้าวันที่ 14'!$B$8:$AC$104,28,FALSE),0)-IFERROR(VLOOKUP(B10,'กะเช้าวันที่ 14'!$B$8:$AC$104,27,FALSE),0) | AD10: =IFERROR(VLOOKUP(B10,'กะเช้าวันที่ 14'!$B$8:$AC$104,27,FALSE),0) | AE10: =IFERROR(VLOOKUP(B10,'กะดึกวันที่ 13'!$B$8:$AC$105,28,FALSE),0) | AG10: =IFERROR(VLOOKUP(B10,'วันที่ 12'!$B$8:$AH$105,28,FALSE),0) | AH10: =IFERROR(VLOOKUP(B10,'วันที่ 14'!$B$8:$AH$106,28,FALSE),0) | AI10: =IFERROR(VLOOKUP(B10,'วันที่ 15'!$B$8:$AH$106,28,FALSE),0) | AJ10: =IFERROR(VLOOKUP(B10,'วันที่ 16'!$B$8:$AH$105,28,FALSE),0) | AK10: =IFERROR(VLOOKUP(B10,'วันที่ 17'!$B$8:$AH$105,28,FALSE),0) | AL10: =IFERROR(VLOOKUP(B10,'วันที่ 18'!$B$8:$AH$104,28,FALSE),0) | AM10: =IFERROR(VLOOKUP(B10,'วันที่ 19'!$B$8:$AH$106,28,FALSE),0) | AN10: =IFERROR(VLOOKUP(B10,'วันที่ 20'!$B$8:$AH$105,28,FALSE),0) | AO10: =IFERROR(VLOOKUP(B10,'วันที่ 21'!$B$8:$AH$106,28,FALSE),0) | AP10: =IFERROR(VLOOKUP(B10,'วันที่ 22'!$B$8:$AH$105,28,FALSE),0) | AQ10: =IFERROR(VLOOKUP(B10,'วันที่ 23'!$B$8:$AH$107,28,FALSE),0) | AR10: =IFERROR(VLOOKUP(B10,'วันที่ 24'!$B$8:$AH$104,28,FALSE),0) | AS10: =IFERROR(VLOOKUP(B10,'วันที่ 25'!$B$8:$AH$106,28,FALSE),0) | AT10: =IFERROR(VLOOKUP(B10,'วันที่ 26'!$B$8:$AH$105,28,FALSE),0) | AU10: =IFERROR(VLOOKUP(B10,'วันที่ 26'!$B$8:$AH$104,28,FALSE),0) | AV10: =IFERROR(VLOOKUP(B10,'วันที่ 30'!$B$8:$AH$107,28,FALSE),0) | AW10: =IFERROR(VLOOKUP(B10,'วันที่ 31'!$B$8:$AG$105,28,FALSE),0) | AX10: =SUM(E10:AW10)
A11: 9 | B11: ธนสิน จินดามณี | C11: =IFERROR(VLOOKUP(B11,Members!B:C,2,FALSE),0) | D11: =IFERROR(VLOOKUP(B11,Members!$B:$H,7,FALSE),0) | E11: =IFERROR(VLOOKUP(B11,'วันที่ 1'!$B$8:$AH$103,28,FALSE),0) - IFERROR(VLOOKUP(B11,'วันที่ 1'!$B$8:$AH$103,27,FALSE),0) | F11: =IFERROR(VLOOKUP(C11,'วันที่ 1'!$B$8:$AH$103,27,FALSE),0) | G11: =IFERROR(VLOOKUP(B11,'วันที่ 1'!$B$8:$AH$103,28,FALSE),0)-IFERROR(VLOOKUP(B11,'วันที่ 1'!$B$8:$AH$103,27,FALSE),0) | H11: =IFERROR(VLOOKUP(B11,'วันที่ 1'!$B$8:$AH$103,27,FALSE),0) | I11: =IFERROR(VLOOKUP(B11,'วันที่ 2'!$B$8:$AF$106,28,FALSE),0)-IFERROR(VLOOKUP(B11,'วันที่ 2'!$B$8:$AF$106,27,FALSE),0) | J11: =IFERROR(VLOOKUP(B11,'วันที่ 2'!$B$8:$AF$106,27,FALSE),0) | K11: =IFERROR(VLOOKUP(B11,'วันที่ 3 กะเช้า'!$B$8:$AK$106,28,FALSE),0)-IFERROR(VLOOKUP(B11,'วันที่ 3 กะเช้า'!$B$8:$AK$106,27,FALSE),0) | L11: =IFERROR(VLOOKUP(B11,'วันที่ 3 กะเช้า'!$B$8:$AK$106,27,FALSE),0) | M11: =IFERROR(VLOOKUP(B11,'วันที่ 4 กะเช้า'!$B$8:$AG$107,28,FALSE),0)-IFERROR(VLOOKUP(B11,'วันที่ 4 กะเช้า'!$B$8:$AG$107,27,FALSE),0) | N11: =IFERROR(VLOOKUP(B11,'วันที่ 4 กะเช้า'!$B$8:$AG$107,27,FALSE),0) | O11: =IFERROR(VLOOKUP(B11,'วันที่ 4 กะเช้า'!$B$8:$AH$106,28,FALSE),0)-IFERROR(VLOOKUP(B11,'วันที่ 4 กะเช้า'!$B$8:$AH$106,27,FALSE),0) | P11: =IFERROR(VLOOKUP(B11,'วันที่ 4 กะเช้า'!$B$8:$AH$106,27,FALSE),0) | Q11: =IFERROR(VLOOKUP(B11,'วันที่ 4 กะเช้า'!$B$8:$AH$106,28,FALSE),0)-IFERROR(VLOOKUP(B11,'วันที่ 4 กะเช้า'!$B$8:$AH$106,27,FALSE),0) | R11: =IFERROR(VLOOKUP(B11,'วันที่ 4 กะเช้า'!$B$8:$AH$106,27,FALSE),0) | S11: =IFERROR(VLOOKUP(B11,'วันที่ 5 กะเช้า'!$B$8:$AH$107,28,FALSE),0)-IFERROR(VLOOKUP(B11,'วันที่ 5 กะเช้า'!$B$8:$AH$107,27,FALSE),0) | T11: =IFERROR(VLOOKUP(B11,'วันที่ 5 กะเช้า'!$B$8:$AH$107,27,FALSE),0) | U11: =IFERROR(VLOOKUP(B11,'วันที่ 5 กะดึก'!$B$8:$AH$106,27,FALSE),0) | V11: =IFERROR(VLOOKUP(B11,'วันที่ 5 กะดึก'!$B$8:$AH$106,27,FALSE),0) | W11: =IFERROR(VLOOKUP(B11,'วันที่ 7'!$B$8:$AH$105,28,FALSE),0)-IFERROR(VLOOKUP(B11,'วันที่ 7'!$B$8:$AH$105,27,FALSE),0) | X11: =IFERROR(VLOOKUP(B11,'วันที่ 7'!$B$8:$AH$105,27,FALSE),0) | Y11: =IFERROR(VLOOKUP(B11,'วันที่ 8'!$B$8:$AH$109,28,FALSE),0)-IFERROR(VLOOKUP(B11,'วันที่ 8'!$B$8:$AH$109,27,FALSE),0) | Z11: =IFERROR(VLOOKUP(B11,'วันที่ 8'!$B$8:$AH$109,27,FALSE),0) | AA11: =IFERROR(VLOOKUP(B11,'กะเช้าวันที่ 12'!$B$8:$AC$102,28,FALSE),0)-IFERROR(VLOOKUP(B11,'กะเช้าวันที่ 12'!$B$8:$AC$102,27,FALSE),0) | AB11: =IFERROR(VLOOKUP(B11,'กะเช้าวันที่ 12'!$B$8:$AC$102,27,FALSE),0) | AC11: =IFERROR(VLOOKUP(B11,'กะเช้าวันที่ 14'!$B$8:$AC$104,28,FALSE),0)-IFERROR(VLOOKUP(B11,'กะเช้าวันที่ 14'!$B$8:$AC$104,27,FALSE),0) | AD11: =IFERROR(VLOOKUP(B11,'กะเช้าวันที่ 14'!$B$8:$AC$104,27,FALSE),0) | AE11: =IFERROR(VLOOKUP(B11,'กะดึกวันที่ 13'!$B$8:$AC$105,28,FALSE),0) | AG11: =IFERROR(VLOOKUP(B11,'วันที่ 12'!$B$8:$AH$105,28,FALSE),0) | AH11: =IFERROR(VLOOKUP(B11,'วันที่ 14'!$B$8:$AH$106,28,FALSE),0) | AI11: =IFERROR(VLOOKUP(B11,'วันที่ 15'!$B$8:$AH$106,28,FALSE),0) | AJ11: =IFERROR(VLOOKUP(B11,'วันที่ 16'!$B$8:$AH$105,28,FALSE),0) | AK11: =IFERROR(VLOOKUP(B11,'วันที่ 17'!$B$8:$AH$105,28,FALSE),0) | AL11: =IFERROR(VLOOKUP(B11,'วันที่ 18'!$B$8:$AH$104,28,FALSE),0) | AM11: =IFERROR(VLOOKUP(B11,'วันที่ 19'!$B$8:$AH$106,28,FALSE),0) | AN11: =IFERROR(VLOOKUP(B11,'วันที่ 20'!$B$8:$AH$105,28,FALSE),0) | AO11: =IFERROR(VLOOKUP(B11,'วันที่ 21'!$B$8:$AH$106,28,FALSE),0) | AP11: =IFERROR(VLOOKUP(B11,'วันที่ 22'!$B$8:$AH$105,28,FALSE),0) | AQ11: =IFERROR(VLOOKUP(B11,'วันที่ 23'!$B$8:$AH$107,28,FALSE),0) | AR11: =IFERROR(VLOOKUP(B11,'วันที่ 24'!$B$8:$AH$104,28,FALSE),0) | AS11: =IFERROR(VLOOKUP(B11,'วันที่ 25'!$B$8:$AH$106,28,FALSE),0) | AT11: =IFERROR(VLOOKUP(B11,'วันที่ 26'!$B$8:$AH$105,28,FALSE),0) | AU11: =IFERROR(VLOOKUP(B11,'วันที่ 26'!$B$8:$AH$104,28,FALSE),0) | AV11: =IFERROR(VLOOKUP(B11,'วันที่ 30'!$B$8:$AH$107,28,FALSE),0) | AW11: =IFERROR(VLOOKUP(B11,'วันที่ 31'!$B$8:$AG$105,28,FALSE),0) | AX11: =SUM(E11:AW11)
A12: 10 | B12: สุรชาติ ดีกล้า | C12: =IFERROR(VLOOKUP(B12,Members!B:C,2,FALSE),0) | D12: =IFERROR(VLOOKUP(B12,Members!$B:$H,7,FALSE),0) | E12: =IFERROR(VLOOKUP(B12,'วันที่ 1'!$B$8:$AH$103,28,FALSE),0) - IFERROR(VLOOKUP(B12,'วันที่ 1'!$B$8:$AH$103,27,FALSE),0) | F12: =IFERROR(VLOOKUP(C12,'วันที่ 1'!$B$8:$AH$103,27,FALSE),0) | G12: =IFERROR(VLOOKUP(B12,'วันที่ 1'!$B$8:$AH$103,28,FALSE),0)-IFERROR(VLOOKUP(B12,'วันที่ 1'!$B$8:$AH$103,27,FALSE),0) | H12: =IFERROR(VLOOKUP(B12,'วันที่ 1'!$B$8:$AH$103,27,FALSE),0) | I12: =IFERROR(VLOOKUP(B12,'วันที่ 2'!$B$8:$AF$106,28,FALSE),0)-IFERROR(VLOOKUP(B12,'วันที่ 2'!$B$8:$AF$106,27,FALSE),0) | J12: =IFERROR(VLOOKUP(B12,'วันที่ 2'!$B$8:$AF$106,27,FALSE),0) | K12: =IFERROR(VLOOKUP(B12,'วันที่ 3 กะเช้า'!$B$8:$AK$106,28,FALSE),0)-IFERROR(VLOOKUP(B12,'วันที่ 3 กะเช้า'!$B$8:$AK$106,27,FALSE),0) | L12: =IFERROR(VLOOKUP(B12,'วันที่ 3 กะเช้า'!$B$8:$AK$106,27,FALSE),0) | M12: =IFERROR(VLOOKUP(B12,'วันที่ 4 กะเช้า'!$B$8:$AG$107,28,FALSE),0)-IFERROR(VLOOKUP(B12,'วันที่ 4 กะเช้า'!$B$8:$AG$107,27,FALSE),0) | N12: =IFERROR(VLOOKUP(B12,'วันที่ 4 กะเช้า'!$B$8:$AG$107,27,FALSE),0) | O12: =IFERROR(VLOOKUP(B12,'วันที่ 4 กะเช้า'!$B$8:$AH$106,28,FALSE),0)-IFERROR(VLOOKUP(B12,'วันที่ 4 กะเช้า'!$B$8:$AH$106,27,FALSE),0) | P12: =IFERROR(VLOOKUP(B12,'วันที่ 4 กะเช้า'!$B$8:$AH$106,27,FALSE),0) | Q12: =IFERROR(VLOOKUP(B12,'วันที่ 4 กะเช้า'!$B$8:$AH$106,28,FALSE),0)-IFERROR(VLOOKUP(B12,'วันที่ 4 กะเช้า'!$B$8:$AH$106,27,FALSE),0) | R12: =IFERROR(VLOOKUP(B12,'วันที่ 4 กะเช้า'!$B$8:$AH$106,27,FALSE),0) | S12: =IFERROR(VLOOKUP(B12,'วันที่ 5 กะเช้า'!$B$8:$AH$107,28,FALSE),0)-IFERROR(VLOOKUP(B12,'วันที่ 5 กะเช้า'!$B$8:$AH$107,27,FALSE),0) | T12: =IFERROR(VLOOKUP(B12,'วันที่ 5 กะเช้า'!$B$8:$AH$107,27,FALSE),0) | U12: =IFERROR(VLOOKUP(B12,'วันที่ 5 กะดึก'!$B$8:$AH$106,27,FALSE),0) | V12: =IFERROR(VLOOKUP(B12,'วันที่ 5 กะดึก'!$B$8:$AH$106,27,FALSE),0) | W12: =IFERROR(VLOOKUP(B12,'วันที่ 7'!$B$8:$AH$105,28,FALSE),0)-IFERROR(VLOOKUP(B12,'วันที่ 7'!$B$8:$AH$105,27,FALSE),0) | X12: =IFERROR(VLOOKUP(B12,'วันที่ 7'!$B$8:$AH$105,27,FALSE),0) | Y12: =IFERROR(VLOOKUP(B12,'วันที่ 8'!$B$8:$AH$109,28,FALSE),0)-IFERROR(VLOOKUP(B12,'วันที่ 8'!$B$8:$AH$109,27,FALSE),0) | Z12: =IFERROR(VLOOKUP(B12,'วันที่ 8'!$B$8:$AH$109,27,FALSE),0) | AA12: =IFERROR(VLOOKUP(B12,'กะเช้าวันที่ 12'!$B$8:$AC$102,28,FALSE),0)-IFERROR(VLOOKUP(B12,'กะเช้าวันที่ 12'!$B$8:$AC$102,27,FALSE),0) | AB12: =IFERROR(VLOOKUP(B12,'กะเช้าวันที่ 12'!$B$8:$AC$102,27,FALSE),0) | AC12: =IFERROR(VLOOKUP(B12,'กะเช้าวันที่ 14'!$B$8:$AC$104,28,FALSE),0)-IFERROR(VLOOKUP(B12,'กะเช้าวันที่ 14'!$B$8:$AC$104,27,FALSE),0) | AD12: =IFERROR(VLOOKUP(B12,'กะเช้าวันที่ 14'!$B$8:$AC$104,27,FALSE),0) | AE12: =IFERROR(VLOOKUP(B12,'กะดึกวันที่ 13'!$B$8:$AC$105,28,FALSE),0) | AG12: =IFERROR(VLOOKUP(B12,'วันที่ 12'!$B$8:$AH$105,28,FALSE),0) | AH12: =IFERROR(VLOOKUP(B12,'วันที่ 14'!$B$8:$AH$106,28,FALSE),0) | AI12: =IFERROR(VLOOKUP(B12,'วันที่ 15'!$B$8:$AH$106,28,FALSE),0) | AJ12: =IFERROR(VLOOKUP(B12,'วันที่ 16'!$B$8:$AH$105,28,FALSE),0) | AK12: =IFERROR(VLOOKUP(B12,'วันที่ 17'!$B$8:$AH$105,28,FALSE),0) | AL12: =IFERROR(VLOOKUP(B12,'วันที่ 18'!$B$8:$AH$104,28,FALSE),0) | AM12: =IFERROR(VLOOKUP(B12,'วันที่ 19'!$B$8:$AH$106,28,FALSE),0) | AN12: =IFERROR(VLOOKUP(B12,'วันที่ 20'!$B$8:$AH$105,28,FALSE),0) | AO12: =IFERROR(VLOOKUP(B12,'วันที่ 21'!$B$8:$AH$106,28,FALSE),0) | AP12: =IFERROR(VLOOKUP(B12,'วันที่ 22'!$B$8:$AH$105,28,FALSE),0) | AQ12: =IFERROR(VLOOKUP(B12,'วันที่ 23'!$B$8:$AH$107,28,FALSE),0) | AR12: =IFERROR(VLOOKUP(B12,'วันที่ 24'!$B$8:$AH$104,28,FALSE),0) | AS12: =IFERROR(VLOOKUP(B12,'วันที่ 25'!$B$8:$AH$106,28,FALSE),0) | AT12: =IFERROR(VLOOKUP(B12,'วันที่ 26'!$B$8:$AH$105,28,FALSE),0) | AU12: =IFERROR(VLOOKUP(B12,'วันที่ 26'!$B$8:$AH$104,28,FALSE),0) | AV12: =IFERROR(VLOOKUP(B12,'วันที่ 30'!$B$8:$AH$107,28,FALSE),0) | AW12: =IFERROR(VLOOKUP(B12,'วันที่ 31'!$B$8:$AG$105,28,FALSE),0) | AX12: =SUM(E12:AW12)
A13: 11 | B13: วิภาวดี ยอดคำ | C13: =IFERROR(VLOOKUP(B13,Members!B:C,2,FALSE),0) | D13: =IFERROR(VLOOKUP(B13,Members!$B:$H,7,FALSE),0) | E13: =IFERROR(VLOOKUP(B13,'วันที่ 1'!$B$8:$AH$103,28,FALSE),0) - IFERROR(VLOOKUP(B13,'วันที่ 1'!$B$8:$AH$103,27,FALSE),0) | F13: =IFERROR(VLOOKUP(C13,'วันที่ 1'!$B$8:$AH$103,27,FALSE),0) | G13: =IFERROR(VLOOKUP(B13,'วันที่ 1'!$B$8:$AH$103,28,FALSE),0)-IFERROR(VLOOKUP(B13,'วันที่ 1'!$B$8:$AH$103,27,FALSE),0) | H13: =IFERROR(VLOOKUP(B13,'วันที่ 1'!$B$8:$AH$103,27,FALSE),0) | I13: =IFERROR(VLOOKUP(B13,'วันที่ 2'!$B$8:$AF$106,28,FALSE),0)-IFERROR(VLOOKUP(B13,'วันที่ 2'!$B$8:$AF$106,27,FALSE),0) | J13: =IFERROR(VLOOKUP(B13,'วันที่ 2'!$B$8:$AF$106,27,FALSE),0) | K13: =IFERROR(VLOOKUP(B13,'วันที่ 3 กะเช้า'!$B$8:$AK$106,28,FALSE),0)-IFERROR(VLOOKUP(B13,'วันที่ 3 กะเช้า'!$B$8:$AK$106,27,FALSE),0) | L13: =IFERROR(VLOOKUP(B13,'วันที่ 3 กะเช้า'!$B$8:$AK$106,27,FALSE),0) | M13: =IFERROR(VLOOKUP(B13,'วันที่ 4 กะเช้า'!$B$8:$AG$107,28,FALSE),0)-IFERROR(VLOOKUP(B13,'วันที่ 4 กะเช้า'!$B$8:$AG$107,27,FALSE),0) | N13: =IFERROR(VLOOKUP(B13,'วันที่ 4 กะเช้า'!$B$8:$AG$107,27,FALSE),0) | O13: =IFERROR(VLOOKUP(B13,'วันที่ 4 กะเช้า'!$B$8:$AH$106,28,FALSE),0)-IFERROR(VLOOKUP(B13,'วันที่ 4 กะเช้า'!$B$8:$AH$106,27,FALSE),0) | P13: =IFERROR(VLOOKUP(B13,'วันที่ 4 กะเช้า'!$B$8:$AH$106,27,FALSE),0) | Q13: =IFERROR(VLOOKUP(B13,'วันที่ 4 กะเช้า'!$B$8:$AH$106,28,FALSE),0)-IFERROR(VLOOKUP(B13,'วันที่ 4 กะเช้า'!$B$8:$AH$106,27,FALSE),0) | R13: =IFERROR(VLOOKUP(B13,'วันที่ 4 กะเช้า'!$B$8:$AH$106,27,FALSE),0) | S13: =IFERROR(VLOOKUP(B13,'วันที่ 5 กะเช้า'!$B$8:$AH$107,28,FALSE),0)-IFERROR(VLOOKUP(B13,'วันที่ 5 กะเช้า'!$B$8:$AH$107,27,FALSE),0) | T13: =IFERROR(VLOOKUP(B13,'วันที่ 5 กะเช้า'!$B$8:$AH$107,27,FALSE),0) | U13: =IFERROR(VLOOKUP(B13,'วันที่ 5 กะดึก'!$B$8:$AH$106,27,FALSE),0) | V13: =IFERROR(VLOOKUP(B13,'วันที่ 5 กะดึก'!$B$8:$AH$106,27,FALSE),0) | W13: =IFERROR(VLOOKUP(B13,'วันที่ 7'!$B$8:$AH$105,28,FALSE),0)-IFERROR(VLOOKUP(B13,'วันที่ 7'!$B$8:$AH$105,27,FALSE),0) | X13: =IFERROR(VLOOKUP(B13,'วันที่ 7'!$B$8:$AH$105,27,FALSE),0) | Y13: =IFERROR(VLOOKUP(B13,'วันที่ 8'!$B$8:$AH$109,28,FALSE),0)-IFERROR(VLOOKUP(B13,'วันที่ 8'!$B$8:$AH$109,27,FALSE),0) | Z13: =IFERROR(VLOOKUP(B13,'วันที่ 8'!$B$8:$AH$109,27,FALSE),0) | AA13: =IFERROR(VLOOKUP(B13,'กะเช้าวันที่ 12'!$B$8:$AC$102,28,FALSE),0)-IFERROR(VLOOKUP(B13,'กะเช้าวันที่ 12'!$B$8:$AC$102,27,FALSE),0) | AB13: =IFERROR(VLOOKUP(B13,'กะเช้าวันที่ 12'!$B$8:$AC$102,27,FALSE),0) | AC13: =IFERROR(VLOOKUP(B13,'กะเช้าวันที่ 14'!$B$8:$AC$104,28,FALSE),0)-IFERROR(VLOOKUP(B13,'กะเช้าวันที่ 14'!$B$8:$AC$104,27,FALSE),0) | AD13: =IFERROR(VLOOKUP(B13,'กะเช้าวันที่ 14'!$B$8:$AC$104,27,FALSE),0) | AE13: =IFERROR(VLOOKUP(B13,'กะดึกวันที่ 13'!$B$8:$AC$105,28,FALSE),0) | AG13: =IFERROR(VLOOKUP(B13,'วันที่ 12'!$B$8:$AH$105,28,FALSE),0) | AH13: =IFERROR(VLOOKUP(B13,'วันที่ 14'!$B$8:$AH$106,28,FALSE),0) | AI13: =IFERROR(VLOOKUP(B13,'วันที่ 15'!$B$8:$AH$106,28,FALSE),0) | AJ13: =IFERROR(VLOOKUP(B13,'วันที่ 16'!$B$8:$AH$105,28,FALSE),0) | AK13: =IFERROR(VLOOKUP(B13,'วันที่ 17'!$B$8:$AH$105,28,FALSE),0) | AL13: =IFERROR(VLOOKUP(B13,'วันที่ 18'!$B$8:$AH$104,28,FALSE),0) | AM13: =IFERROR(VLOOKUP(B13,'วันที่ 19'!$B$8:$AH$106,28,FALSE),0) | AN13: =IFERROR(VLOOKUP(B13,'วันที่ 20'!$B$8:$AH$105,28,FALSE),0) | AO13: =IFERROR(VLOOKUP(B13,'วันที่ 21'!$B$8:$AH$106,28,FALSE),0) | AP13: =IFERROR(VLOOKUP(B13,'วันที่ 22'!$B$8:$AH$105,28,FALSE),0) | AQ13: =IFERROR(VLOOKUP(B13,'วันที่ 23'!$B$8:$AH$107,28,FALSE),0) | AR13: =IFERROR(VLOOKUP(B13,'วันที่ 24'!$B$8:$AH$104,28,FALSE),0) | AS13: =IFERROR(VLOOKUP(B13,'วันที่ 25'!$B$8:$AH$106,28,FALSE),0) | AT13: =IFERROR(VLOOKUP(B13,'วันที่ 26'!$B$8:$AH$105,28,FALSE),0) | AU13: =IFERROR(VLOOKUP(B13,'วันที่ 26'!$B$8:$AH$104,28,FALSE),0) | AV13: =IFERROR(VLOOKUP(B13,'วันที่ 30'!$B$8:$AH$107,28,FALSE),0) | AW13: =IFERROR(VLOOKUP(B13,'วันที่ 31'!$B$8:$AG$105,28,FALSE),0) | AX13: =SUM(E13:AW13)
A14: 12 | B14: ฟารดา สารจันทร์ | C14: =IFERROR(VLOOKUP(B14,Members!B:C,2,FALSE),0) | D14: =IFERROR(VLOOKUP(B14,Members!$B:$H,7,FALSE),0) | E14: =IFERROR(VLOOKUP(B14,'วันที่ 1'!$B$8:$AH$103,28,FALSE),0) - IFERROR(VLOOKUP(B14,'วันที่ 1'!$B$8:$AH$103,27,FALSE),0) | F14: =IFERROR(VLOOKUP(C14,'วันที่ 1'!$B$8:$AH$103,27,FALSE),0) | G14: =IFERROR(VLOOKUP(B14,'วันที่ 1'!$B$8:$AH$103,28,FALSE),0)-IFERROR(VLOOKUP(B14,'วันที่ 1'!$B$8:$AH$103,27,FALSE),0) | H14: =IFERROR(VLOOKUP(B14,'วันที่ 1'!$B$8:$AH$103,27,FALSE),0) | I14: =IFERROR(VLOOKUP(B14,'วันที่ 2'!$B$8:$AF$106,28,FALSE),0)-IFERROR(VLOOKUP(B14,'วันที่ 2'!$B$8:$AF$106,27,FALSE),0) | J14: =IFERROR(VLOOKUP(B14,'วันที่ 2'!$B$8:$AF$106,27,FALSE),0) | K14: =IFERROR(VLOOKUP(B14,'วันที่ 3 กะเช้า'!$B$8:$AK$106,28,FALSE),0)-IFERROR(VLOOKUP(B14,'วันที่ 3 กะเช้า'!$B$8:$AK$106,27,FALSE),0) | L14: =IFERROR(VLOOKUP(B14,'วันที่ 3 กะเช้า'!$B$8:$AK$106,27,FALSE),0) | M14: =IFERROR(VLOOKUP(B14,'วันที่ 4 กะเช้า'!$B$8:$AG$107,28,FALSE),0)-IFERROR(VLOOKUP(B14,'วันที่ 4 กะเช้า'!$B$8:$AG$107,27,FALSE),0) | N14: =IFERROR(VLOOKUP(B14,'วันที่ 4 กะเช้า'!$B$8:$AG$107,27,FALSE),0) | O14: =IFERROR(VLOOKUP(B14,'วันที่ 4 กะเช้า'!$B$8:$AH$106,28,FALSE),0)-IFERROR(VLOOKUP(B14,'วันที่ 4 กะเช้า'!$B$8:$AH$106,27,FALSE),0) | P14: =IFERROR(VLOOKUP(B14,'วันที่ 4 กะเช้า'!$B$8:$AH$106,27,FALSE),0) | Q14: =IFERROR(VLOOKUP(B14,'วันที่ 4 กะเช้า'!$B$8:$AH$106,28,FALSE),0)-IFERROR(VLOOKUP(B14,'วันที่ 4 กะเช้า'!$B$8:$AH$106,27,FALSE),0) | R14: =IFERROR(VLOOKUP(B14,'วันที่ 4 กะเช้า'!$B$8:$AH$106,27,FALSE),0) | S14: =IFERROR(VLOOKUP(B14,'วันที่ 5 กะเช้า'!$B$8:$AH$107,28,FALSE),0)-IFERROR(VLOOKUP(B14,'วันที่ 5 กะเช้า'!$B$8:$AH$107,27,FALSE),0) | T14: =IFERROR(VLOOKUP(B14,'วันที่ 5 กะเช้า'!$B$8:$AH$107,27,FALSE),0) | U14: =IFERROR(VLOOKUP(B14,'วันที่ 5 กะดึก'!$B$8:$AH$106,27,FALSE),0) | V14: =IFERROR(VLOOKUP(B14,'วันที่ 5 กะดึก'!$B$8:$AH$106,27,FALSE),0) | W14: =IFERROR(VLOOKUP(B14,'วันที่ 7'!$B$8:$AH$105,28,FALSE),0)-IFERROR(VLOOKUP(B14,'วันที่ 7'!$B$8:$AH$105,27,FALSE),0) | X14: =IFERROR(VLOOKUP(B14,'วันที่ 7'!$B$8:$AH$105,27,FALSE),0) | Y14: =IFERROR(VLOOKUP(B14,'วันที่ 8'!$B$8:$AH$109,28,FALSE),0)-IFERROR(VLOOKUP(B14,'วันที่ 8'!$B$8:$AH$109,27,FALSE),0) | Z14: =IFERROR(VLOOKUP(B14,'วันที่ 8'!$B$8:$AH$109,27,FALSE),0) | AA14: =IFERROR(VLOOKUP(B14,'กะเช้าวันที่ 12'!$B$8:$AC$102,28,FALSE),0)-IFERROR(VLOOKUP(B14,'กะเช้าวันที่ 12'!$B$8:$AC$102,27,FALSE),0) | AB14: =IFERROR(VLOOKUP(B14,'กะเช้าวันที่ 12'!$B$8:$AC$102,27,FALSE),0) | AC14: =IFERROR(VLOOKUP(B14,'กะเช้าวันที่ 14'!$B$8:$AC$104,28,FALSE),0)-IFERROR(VLOOKUP(B14,'กะเช้าวันที่ 14'!$B$8:$AC$104,27,FALSE),0) | AD14: =IFERROR(VLOOKUP(B14,'กะเช้าวันที่ 14'!$B$8:$AC$104,27,FALSE),0) | AE14: =IFERROR(VLOOKUP(B14,'กะดึกวันที่ 13'!$B$8:$AC$105,28,FALSE),0) | AG14: =IFERROR(VLOOKUP(B14,'วันที่ 12'!$B$8:$AH$105,28,FALSE),0) | AH14: =IFERROR(VLOOKUP(B14,'วันที่ 14'!$B$8:$AH$106,28,FALSE),0) | AI14: =IFERROR(VLOOKUP(B14,'วันที่ 15'!$B$8:$AH$106,28,FALSE),0) | AJ14: =IFERROR(VLOOKUP(B14,'วันที่ 16'!$B$8:$AH$105,28,FALSE),0) | AK14: =IFERROR(VLOOKUP(B14,'วันที่ 17'!$B$8:$AH$105,28,FALSE),0) | AL14: =IFERROR(VLOOKUP(B14,'วันที่ 18'!$B$8:$AH$104,28,FALSE),0) | AM14: =IFERROR(VLOOKUP(B14,'วันที่ 19'!$B$8:$AH$106,28,FALSE),0) | AN14: =IFERROR(VLOOKUP(B14,'วันที่ 20'!$B$8:$AH$105,28,FALSE),0) | AO14: =IFERROR(VLOOKUP(B14,'วันที่ 21'!$B$8:$AH$106,28,FALSE),0) | AP14: =IFERROR(VLOOKUP(B14,'วันที่ 22'!$B$8:$AH$105,28,FALSE),0) | AQ14: =IFERROR(VLOOKUP(B14,'วันที่ 23'!$B$8:$AH$107,28,FALSE),0) | AR14: =IFERROR(VLOOKUP(B14,'วันที่ 24'!$B$8:$AH$104,28,FALSE),0) | AS14: =IFERROR(VLOOKUP(B14,'วันที่ 25'!$B$8:$AH$106,28,FALSE),0) | AT14: =IFERROR(VLOOKUP(B14,'วันที่ 26'!$B$8:$AH$105,28,FALSE),0) | AU14: =IFERROR(VLOOKUP(B14,'วันที่ 26'!$B$8:$AH$104,28,FALSE),0) | AV14: =IFERROR(VLOOKUP(B14,'วันที่ 30'!$B$8:$AH$107,28,FALSE),0) | AW14: =IFERROR(VLOOKUP(B14,'วันที่ 31'!$B$8:$AG$105,28,FALSE),0) | AX14: =SUM(E14:AW14)
... A83: 85 | B83: ชลธิชา ภูพานแดง | C83: =IFERROR(VLOOKUP(B83,Members!B:C,2,FALSE),0) | D83: =IFERROR(VLOOKUP(B83,Members!$B:$H,7,FALSE),0) | E83: =IFERROR(VLOOKUP(B83,'วันที่ 1'!$B$8:$AH$103,28,FALSE),0) - IFERROR(VLOOKUP(B83,'วันที่ 1'!$B$8:$AH$103,27,FALSE),0) | F83: =IFERROR(VLOOKUP(C83,'วันที่ 1'!$B$8:$AH$103,27,FALSE),0) | G83: =IFERROR(VLOOKUP(B83,'วันที่ 1'!$B$8:$AH$103,28,FALSE),0)-IFERROR(VLOOKUP(B83,'วันที่ 1'!$B$8:$AH$103,27,FALSE),0) | H83: =IFERROR(VLOOKUP(B83,'วันที่ 1'!$B$8:$AH$103,27,FALSE),0) | I83: =IFERROR(VLOOKUP(B83,'วันที่ 2'!$B$8:$AF$106,28,FALSE),0)-IFERROR(VLOOKUP(B83,'วันที่ 2'!$B$8:$AF$106,27,FALSE),0) | J83: =IFERROR(VLOOKUP(B83,'วันที่ 2'!$B$8:$AF$106,27,FALSE),0) | K83: =IFERROR(VLOOKUP(B83,'วันที่ 3 กะเช้า'!$B$8:$AK$106,28,FALSE),0)-IFERROR(VLOOKUP(B83,'วันที่ 3 กะเช้า'!$B$8:$AK$106,27,FALSE),0) | L83: =IFERROR(VLOOKUP(B83,'วันที่ 3 กะเช้า'!$B$8:$AK$106,27,FALSE),0) | M83: =IFERROR(VLOOKUP(B83,'วันที่ 4 กะเช้า'!$B$8:$AG$107,28,FALSE),0)-IFERROR(VLOOKUP(B83,'วันที่ 4 กะเช้า'!$B$8:$AG$107,27,FALSE),0) | N83: =IFERROR(VLOOKUP(B83,'วันที่ 4 กะเช้า'!$B$8:$AG$107,27,FALSE),0) | O83: =IFERROR(VLOOKUP(B83,'วันที่ 4 กะเช้า'!$B$8:$AH$106,28,FALSE),0)-IFERROR(VLOOKUP(B83,'วันที่ 4 กะเช้า'!$B$8:$AH$106,27,FALSE),0) | P83: =IFERROR(VLOOKUP(B83,'วันที่ 4 กะเช้า'!$B$8:$AH$106,27,FALSE),0) | Q83: =IFERROR(VLOOKUP(B83,'วันที่ 4 กะเช้า'!$B$8:$AH$106,28,FALSE),0)-IFERROR(VLOOKUP(B83,'วันที่ 4 กะเช้า'!$B$8:$AH$106,27,FALSE),0) | R83: =IFERROR(VLOOKUP(B83,'วันที่ 4 กะเช้า'!$B$8:$AH$106,27,FALSE),0) | S83: =IFERROR(VLOOKUP(B83,'วันที่ 5 กะเช้า'!$B$8:$AH$107,28,FALSE),0)-IFERROR(VLOOKUP(B83,'วันที่ 5 กะเช้า'!$B$8:$AH$107,27,FALSE),0) | T83: =IFERROR(VLOOKUP(B83,'วันที่ 5 กะเช้า'!$B$8:$AH$107,27,FALSE),0) | U83: =IFERROR(VLOOKUP(B83,'วันที่ 5 กะดึก'!$B$8:$AH$106,27,FALSE),0) | V83: =IFERROR(VLOOKUP(B83,'วันที่ 5 กะดึก'!$B$8:$AH$106,27,FALSE),0) | W83: =IFERROR(VLOOKUP(B83,'วันที่ 7'!$B$8:$AH$105,28,FALSE),0)-IFERROR(VLOOKUP(B83,'วันที่ 7'!$B$8:$AH$105,27,FALSE),0) | X83: =IFERROR(VLOOKUP(B83,'วันที่ 7'!$B$8:$AH$105,27,FALSE),0) | Y83: =IFERROR(VLOOKUP(B83,'วันที่ 8'!$B$8:$AH$109,28,FALSE),0)-IFERROR(VLOOKUP(B83,'วันที่ 8'!$B$8:$AH$109,27,FALSE),0) | Z83: =IFERROR(VLOOKUP(B83,'วันที่ 8'!$B$8:$AH$109,27,FALSE),0) | AA83: =IFERROR(VLOOKUP(B83,'กะเช้าวันที่ 12'!$B$8:$AC$102,28,FALSE),0)-IFERROR(VLOOKUP(B83,'กะเช้าวันที่ 12'!$B$8:$AC$102,27,FALSE),0) | AB83: =IFERROR(VLOOKUP(B83,'กะเช้าวันที่ 12'!$B$8:$AC$102,27,FALSE),0) | AC83: =IFERROR(VLOOKUP(B83,'กะเช้าวันที่ 14'!$B$8:$AC$104,28,FALSE),0)-IFERROR(VLOOKUP(B83,'กะเช้าวันที่ 14'!$B$8:$AC$104,27,FALSE),0) | AD83: =IFERROR(VLOOKUP(B83,'กะเช้าวันที่ 14'!$B$8:$AC$104,27,FALSE),0) | AE83: =IFERROR(VLOOKUP(B83,'กะดึกวันที่ 13'!$B$8:$AC$105,28,FALSE),0) | AG83: =IFERROR(VLOOKUP(B83,'วันที่ 12'!$B$8:$AH$105,28,FALSE),0) | AH83: =IFERROR(VLOOKUP(B83,'วันที่ 14'!$B$8:$AH$106,28,FALSE),0) | AI83: =IFERROR(VLOOKUP(B83,'วันที่ 15'!$B$8:$AH$106,28,FALSE),0) | AJ83: =IFERROR(VLOOKUP(B83,'วันที่ 16'!$B$8:$AH$105,28,FALSE),0) | AK83: =IFERROR(VLOOKUP(B83,'วันที่ 17'!$B$8:$AH$105,28,FALSE),0) | AL83: =IFERROR(VLOOKUP(B83,'วันที่ 18'!$B$8:$AH$104,28,FALSE),0) | AM83: =IFERROR(VLOOKUP(B83,'วันที่ 19'!$B$8:$AH$106,28,FALSE),0) | AN83: =IFERROR(VLOOKUP(B83,'วันที่ 20'!$B$8:$AH$105,28,FALSE),0) | AO83: =IFERROR(VLOOKUP(B83,'วันที่ 21'!$B$8:$AH$106,28,FALSE),0) | AP83: =IFERROR(VLOOKUP(B83,'วันที่ 22'!$B$8:$AH$105,28,FALSE),0) | AQ83: =IFERROR(VLOOKUP(B83,'วันที่ 23'!$B$8:$AH$107,28,FALSE),0) | AR83: =IFERROR(VLOOKUP(B83,'วันที่ 24'!$B$8:$AH$104,28,FALSE),0) | AS83: =IFERROR(VLOOKUP(B83,'วันที่ 25'!$B$8:$AH$106,28,FALSE),0) | AT83: =IFERROR(VLOOKUP(B83,'วันที่ 26'!$B$8:$AH$105,28,FALSE),0) | AU83: =IFERROR(VLOOKUP(B83,'วันที่ 26'!$B$8:$AH$104,28,FALSE),0) | AV83: =IFERROR(VLOOKUP(B83,'วันที่ 30'!$B$8:$AH$107,28,FALSE),0) | AW83: =IFERROR(VLOOKUP(B83,'วันที่ 31'!$B$8:$AG$105,28,FALSE),0) | AX83: =SUM(E83:AW83)
